2022-03-18 10:49:03 WARNING (SyncWorker_0) [homeassistant.loader] We found a custom integration eskom_loadshedding which has not been tested by Home Assistant. This component might cause stability problems, be sure to disable it if you experience issues with Home Assistant
2022-03-18 10:49:03 WARNING (SyncWorker_1) [homeassistant.loader] We found a custom integration sonoff which has not been tested by Home Assistant. This component might cause stability problems, be sure to disable it if you experience issues with Home Assistant
2022-03-18 10:49:03 WARNING (SyncWorker_2) [homeassistant.loader] We found a custom integration hacs which has not been tested by Home Assistant. This component might cause stability problems, be sure to disable it if you experience issues with Home Assistant
2022-03-18 10:49:11 WARNING (Recorder) [homeassistant.components.recorder.util] Ended unfinished session (id=56 from 2022-03-13 10:14:12)
2022-03-18 10:49:25 WARNING (MainThread) [homeassistant.setup] Setup of hassio is taking over 10 seconds.
2022-03-18 10:49:37 WARNING (MainThread) [homeassistant.helpers.entity] Entity sensor.eskom_loadshedding_stage (<class 'custom_components.eskom_loadshedding.sensor.EskomStageSensor'>) implements device_state_attributes. Please report it to the custom component author.
2022-03-18 10:49:50 WARNING (MainThread) [homeassistant.components.konnected.panel] Exception trying to connect to panel: 
2022-03-18 10:49:51 WARNING (MainThread) [homeassistant.components.konnected.panel] Exception trying to connect to panel: 
2022-03-18 10:49:51 WARNING (MainThread) [homeassistant.components.konnected.panel] Exception trying to connect to panel: 
2022-03-18 10:49:51 WARNING (MainThread) [homeassistant.components.konnected.panel] Exception trying to connect to panel: 
2022-03-18 10:50:02 ERROR (MainThread) [homeassistant.components.hassio.handler] Timeout on /addons/core_mosquitto/info request
2022-03-18 10:50:02 ERROR (MainThread) [homeassistant.components.hassio.discovery] Can't read add-on info: 
2022-03-18 10:50:19 WARNING (MainThread) [homeassistant.components.switch] Updating adguard switch took longer than the scheduled update interval 0:00:10
2022-03-18 10:50:23 WARNING (MainThread) [homeassistant.components.konnected.panel] Exception trying to connect to panel: 
2022-03-18 10:50:28 WARNING (MainThread) [homeassistant.components.konnected.panel] Exception trying to connect to panel: 
2022-03-18 10:50:28 WARNING (MainThread) [homeassistant.components.konnected.panel] Exception trying to connect to panel: 
2022-03-18 10:50:29 WARNING (MainThread) [homeassistant.components.konnected.panel] Exception trying to connect to panel: 
2022-03-18 11:25:56 ERROR (MainThread) [homeassistant.components.ipp.coordinator] Error fetching ipp data: Invalid response from API: Timeout occurred while connecting to IPP server.
2022-03-18 11:42:41 ERROR (MainThread) [homeassistant.components.ipp.coordinator] Error fetching ipp data: Invalid response from API: Timeout occurred while connecting to IPP server.
2022-03-18 12:02:17 ERROR (MainThread) [homeassistant.components.ipp.coordinator] Error fetching ipp data: Invalid response from API: Timeout occurred while connecting to IPP server.
2022-03-18 12:57:56 ERROR (MainThread) [homeassistant.components.ipp.coordinator] Error fetching ipp data: Invalid response from API: Timeout occurred while connecting to IPP server.
2022-03-18 13:33:40 ERROR (MainThread) [homeassistant.components.apple_tv.config_flow] Unexpected exception
Traceback (most recent call last):
  File "/usr/src/homeassistant/homeassistant/components/apple_tv/config_flow.py", line 270, in async_find_device_wrapper
    await self.async_find_device(allow_exist)
  File "/usr/src/homeassistant/homeassistant/components/apple_tv/config_flow.py", line 283, in async_find_device
    self.atv, self.atv_identifiers = await device_scan(
  File "/usr/src/homeassistant/homeassistant/components/apple_tv/config_flow.py", line 57, in device_scan
    scan_result = await scan(loop, timeout=3, hosts=_host_filter(), aiozc=aiozc)
  File "/usr/local/lib/python3.9/site-packages/pyatv/__init__.py", line 58, in scan
    aiozc, hosts=[IPv4Address(host) for host in hosts]
  File "/usr/local/lib/python3.9/site-packages/pyatv/__init__.py", line 58, in <listcomp>
    aiozc, hosts=[IPv4Address(host) for host in hosts]
  File "/usr/local/lib/python3.9/ipaddress.py", line 1307, in __init__
    self._ip = self._ip_int_from_string(addr_str)
  File "/usr/local/lib/python3.9/ipaddress.py", line 1194, in _ip_int_from_string
    raise AddressValueError("Expected 4 octets in %r" % ip_str)
ipaddress.AddressValueError: Expected 4 octets in '2c0f:f4c0:118c:40e0:db:f108:bf16:6b22'
2022-03-18 13:37:56 ERROR (MainThread) [homeassistant.components.apple_tv.config_flow] Unexpected exception
Traceback (most recent call last):
  File "/usr/src/homeassistant/homeassistant/components/apple_tv/config_flow.py", line 270, in async_find_device_wrapper
    await self.async_find_device(allow_exist)
  File "/usr/src/homeassistant/homeassistant/components/apple_tv/config_flow.py", line 283, in async_find_device
    self.atv, self.atv_identifiers = await device_scan(
  File "/usr/src/homeassistant/homeassistant/components/apple_tv/config_flow.py", line 57, in device_scan
    scan_result = await scan(loop, timeout=3, hosts=_host_filter(), aiozc=aiozc)
  File "/usr/local/lib/python3.9/site-packages/pyatv/__init__.py", line 58, in scan
    aiozc, hosts=[IPv4Address(host) for host in hosts]
  File "/usr/local/lib/python3.9/site-packages/pyatv/__init__.py", line 58, in <listcomp>
    aiozc, hosts=[IPv4Address(host) for host in hosts]
  File "/usr/local/lib/python3.9/ipaddress.py", line 1307, in __init__
    self._ip = self._ip_int_from_string(addr_str)
  File "/usr/local/lib/python3.9/ipaddress.py", line 1194, in _ip_int_from_string
    raise AddressValueError("Expected 4 octets in %r" % ip_str)
ipaddress.AddressValueError: Expected 4 octets in '2c0f:f4c0:118c:40e0:db:f108:bf16:6b22'
2022-03-18 13:49:29 ERROR (MainThread) [homeassistant.components.ipp.coordinator] Error fetching ipp data: Invalid response from API: Timeout occurred while connecting to IPP server.
2022-03-18 14:28:54 ERROR (MainThread) [homeassistant.components.ipp.coordinator] Error fetching ipp data: Invalid response from API: Timeout occurred while connecting to IPP server.
2022-03-18 15:14:28 ERROR (MainThread) [homeassistant.components.ipp.coordinator] Error fetching ipp data: Invalid response from API: Timeout occurred while connecting to IPP server.
2022-03-18 15:19:03 ERROR (MainThread) [homeassistant.components.apple_tv.config_flow] Unexpected exception
Traceback (most recent call last):
  File "/usr/src/homeassistant/homeassistant/components/apple_tv/config_flow.py", line 270, in async_find_device_wrapper
    await self.async_find_device(allow_exist)
  File "/usr/src/homeassistant/homeassistant/components/apple_tv/config_flow.py", line 283, in async_find_device
    self.atv, self.atv_identifiers = await device_scan(
  File "/usr/src/homeassistant/homeassistant/components/apple_tv/config_flow.py", line 57, in device_scan
    scan_result = await scan(loop, timeout=3, hosts=_host_filter(), aiozc=aiozc)
  File "/usr/local/lib/python3.9/site-packages/pyatv/__init__.py", line 58, in scan
    aiozc, hosts=[IPv4Address(host) for host in hosts]
  File "/usr/local/lib/python3.9/site-packages/pyatv/__init__.py", line 58, in <listcomp>
    aiozc, hosts=[IPv4Address(host) for host in hosts]
  File "/usr/local/lib/python3.9/ipaddress.py", line 1307, in __init__
    self._ip = self._ip_int_from_string(addr_str)
  File "/usr/local/lib/python3.9/ipaddress.py", line 1194, in _ip_int_from_string
    raise AddressValueError("Expected 4 octets in %r" % ip_str)
ipaddress.AddressValueError: Expected 4 octets in '2c0f:f4c0:118c:40e0:db:f108:bf16:6b22'
2022-03-18 15:20:33 ERROR (MainThread) [homeassistant.components.apple_tv.config_flow] Unexpected exception
Traceback (most recent call last):
  File "/usr/src/homeassistant/homeassistant/components/apple_tv/config_flow.py", line 270, in async_find_device_wrapper
    await self.async_find_device(allow_exist)
  File "/usr/src/homeassistant/homeassistant/components/apple_tv/config_flow.py", line 283, in async_find_device
    self.atv, self.atv_identifiers = await device_scan(
  File "/usr/src/homeassistant/homeassistant/components/apple_tv/config_flow.py", line 57, in device_scan
    scan_result = await scan(loop, timeout=3, hosts=_host_filter(), aiozc=aiozc)
  File "/usr/local/lib/python3.9/site-packages/pyatv/__init__.py", line 58, in scan
    aiozc, hosts=[IPv4Address(host) for host in hosts]
  File "/usr/local/lib/python3.9/site-packages/pyatv/__init__.py", line 58, in <listcomp>
    aiozc, hosts=[IPv4Address(host) for host in hosts]
  File "/usr/local/lib/python3.9/ipaddress.py", line 1307, in __init__
    self._ip = self._ip_int_from_string(addr_str)
  File "/usr/local/lib/python3.9/ipaddress.py", line 1194, in _ip_int_from_string
    raise AddressValueError("Expected 4 octets in %r" % ip_str)
ipaddress.AddressValueError: Expected 4 octets in '2c0f:f4c0:118c:40e0:db:f108:bf16:6b22'
2022-03-18 17:46:40 ERROR (MainThread) [homeassistant.components.ipp.coordinator] Error fetching ipp data: Invalid response from API: Timeout occurred while connecting to IPP server.
2022-03-18 18:11:26 ERROR (MainThread) [homeassistant.components.ipp.coordinator] Error fetching ipp data: Invalid response from API: Timeout occurred while connecting to IPP server.
2022-03-18 20:03:04 ERROR (MainThread) [homeassistant.components.apple_tv.config_flow] Unexpected exception
Traceback (most recent call last):
  File "/usr/src/homeassistant/homeassistant/components/apple_tv/config_flow.py", line 270, in async_find_device_wrapper
    await self.async_find_device(allow_exist)
  File "/usr/src/homeassistant/homeassistant/components/apple_tv/config_flow.py", line 283, in async_find_device
    self.atv, self.atv_identifiers = await device_scan(
  File "/usr/src/homeassistant/homeassistant/components/apple_tv/config_flow.py", line 57, in device_scan
    scan_result = await scan(loop, timeout=3, hosts=_host_filter(), aiozc=aiozc)
  File "/usr/local/lib/python3.9/site-packages/pyatv/__init__.py", line 58, in scan
    aiozc, hosts=[IPv4Address(host) for host in hosts]
  File "/usr/local/lib/python3.9/site-packages/pyatv/__init__.py", line 58, in <listcomp>
    aiozc, hosts=[IPv4Address(host) for host in hosts]
  File "/usr/local/lib/python3.9/ipaddress.py", line 1307, in __init__
    self._ip = self._ip_int_from_string(addr_str)
  File "/usr/local/lib/python3.9/ipaddress.py", line 1194, in _ip_int_from_string
    raise AddressValueError("Expected 4 octets in %r" % ip_str)
ipaddress.AddressValueError: Expected 4 octets in '2c0f:f4c0:118c:40e0:db:f108:bf16:6b22'
2022-03-18 20:43:25 ERROR (MainThread) [homeassistant.components.ipp.coordinator] Error fetching ipp data: Invalid response from API: Error occurred while communicating with IPP server.
2022-03-18 22:48:44 ERROR (MainThread) [homeassistant.components.apple_tv.config_flow] Unexpected exception
Traceback (most recent call last):
  File "/usr/src/homeassistant/homeassistant/components/apple_tv/config_flow.py", line 270, in async_find_device_wrapper
    await self.async_find_device(allow_exist)
  File "/usr/src/homeassistant/homeassistant/components/apple_tv/config_flow.py", line 283, in async_find_device
    self.atv, self.atv_identifiers = await device_scan(
  File "/usr/src/homeassistant/homeassistant/components/apple_tv/config_flow.py", line 57, in device_scan
    scan_result = await scan(loop, timeout=3, hosts=_host_filter(), aiozc=aiozc)
  File "/usr/local/lib/python3.9/site-packages/pyatv/__init__.py", line 58, in scan
    aiozc, hosts=[IPv4Address(host) for host in hosts]
  File "/usr/local/lib/python3.9/site-packages/pyatv/__init__.py", line 58, in <listcomp>
    aiozc, hosts=[IPv4Address(host) for host in hosts]
  File "/usr/local/lib/python3.9/ipaddress.py", line 1307, in __init__
    self._ip = self._ip_int_from_string(addr_str)
  File "/usr/local/lib/python3.9/ipaddress.py", line 1194, in _ip_int_from_string
    raise AddressValueError("Expected 4 octets in %r" % ip_str)
ipaddress.AddressValueError: Expected 4 octets in '2c0f:f4c0:118c:40e0:db:f108:bf16:6b22'
2022-03-18 22:53:00 ERROR (MainThread) [homeassistant.components.apple_tv.config_flow] Unexpected exception
Traceback (most recent call last):
  File "/usr/src/homeassistant/homeassistant/components/apple_tv/config_flow.py", line 270, in async_find_device_wrapper
    await self.async_find_device(allow_exist)
  File "/usr/src/homeassistant/homeassistant/components/apple_tv/config_flow.py", line 283, in async_find_device
    self.atv, self.atv_identifiers = await device_scan(
  File "/usr/src/homeassistant/homeassistant/components/apple_tv/config_flow.py", line 57, in device_scan
    scan_result = await scan(loop, timeout=3, hosts=_host_filter(), aiozc=aiozc)
  File "/usr/local/lib/python3.9/site-packages/pyatv/__init__.py", line 58, in scan
    aiozc, hosts=[IPv4Address(host) for host in hosts]
  File "/usr/local/lib/python3.9/site-packages/pyatv/__init__.py", line 58, in <listcomp>
    aiozc, hosts=[IPv4Address(host) for host in hosts]
  File "/usr/local/lib/python3.9/ipaddress.py", line 1307, in __init__
    self._ip = self._ip_int_from_string(addr_str)
  File "/usr/local/lib/python3.9/ipaddress.py", line 1194, in _ip_int_from_string
    raise AddressValueError("Expected 4 octets in %r" % ip_str)
ipaddress.AddressValueError: Expected 4 octets in '2c0f:f4c0:118c:40e0:db:f108:bf16:6b22'
2022-03-18 23:53:38 ERROR (MainThread) [homeassistant.components.ipp.coordinator] Error fetching ipp data: Invalid response from API: Timeout occurred while connecting to IPP server.
2022-03-19 03:54:55 ERROR (MainThread) [homeassistant.components.forecast_solar] Timeout fetching forecast_solar data
2022-03-19 04:53:00 ERROR (MainThread) [homeassistant.components.ipp.coordinator] Error fetching ipp data: Invalid response from API: Timeout occurred while connecting to IPP server.
2022-03-19 04:55:27 ERROR (MainThread) [homeassistant.components.forecast_solar] Unexpected error fetching forecast_solar data: The Forecast.Solar API is unreachable, 
Traceback (most recent call last):
  File "/usr/src/homeassistant/homeassistant/helpers/update_coordinator.py", line 187, in _async_refresh
    self.data = await self._async_update_data()
  File "/usr/src/homeassistant/homeassistant/helpers/update_coordinator.py", line 147, in _async_update_data
    return await self.update_method()
  File "/usr/local/lib/python3.9/site-packages/forecast_solar/__init__.py", line 138, in estimate
    data = await self._request(
  File "/usr/local/lib/python3.9/site-packages/forecast_solar/__init__.py", line 105, in _request
    raise ForecastSolarConnectionError(
forecast_solar.exceptions.ForecastSolarConnectionError: The Forecast.Solar API is unreachable, 
2022-03-19 05:55:59 ERROR (MainThread) [homeassistant.components.forecast_solar] Unexpected error fetching forecast_solar data: The Forecast.Solar API is unreachable, 
Traceback (most recent call last):
  File "/usr/src/homeassistant/homeassistant/helpers/update_coordinator.py", line 187, in _async_refresh
    self.data = await self._async_update_data()
  File "/usr/src/homeassistant/homeassistant/helpers/update_coordinator.py", line 147, in _async_update_data
    return await self.update_method()
  File "/usr/local/lib/python3.9/site-packages/forecast_solar/__init__.py", line 138, in estimate
    data = await self._request(
  File "/usr/local/lib/python3.9/site-packages/forecast_solar/__init__.py", line 105, in _request
    raise ForecastSolarConnectionError(
forecast_solar.exceptions.ForecastSolarConnectionError: The Forecast.Solar API is unreachable, 
2022-03-19 07:26:14 ERROR (MainThread) [homeassistant.components.ipp.coordinator] Error fetching ipp data: Invalid response from API: Timeout occurred while connecting to IPP server.
2022-03-19 07:35:04 ERROR (MainThread) [homeassistant.components.apple_tv.config_flow] Unexpected exception
Traceback (most recent call last):
  File "/usr/src/homeassistant/homeassistant/components/apple_tv/config_flow.py", line 270, in async_find_device_wrapper
    await self.async_find_device(allow_exist)
  File "/usr/src/homeassistant/homeassistant/components/apple_tv/config_flow.py", line 283, in async_find_device
    self.atv, self.atv_identifiers = await device_scan(
  File "/usr/src/homeassistant/homeassistant/components/apple_tv/config_flow.py", line 57, in device_scan
    scan_result = await scan(loop, timeout=3, hosts=_host_filter(), aiozc=aiozc)
  File "/usr/local/lib/python3.9/site-packages/pyatv/__init__.py", line 58, in scan
    aiozc, hosts=[IPv4Address(host) for host in hosts]
  File "/usr/local/lib/python3.9/site-packages/pyatv/__init__.py", line 58, in <listcomp>
    aiozc, hosts=[IPv4Address(host) for host in hosts]
  File "/usr/local/lib/python3.9/ipaddress.py", line 1307, in __init__
    self._ip = self._ip_int_from_string(addr_str)
  File "/usr/local/lib/python3.9/ipaddress.py", line 1194, in _ip_int_from_string
    raise AddressValueError("Expected 4 octets in %r" % ip_str)
ipaddress.AddressValueError: Expected 4 octets in '2c0f:f4c0:118c:40e0:db:f108:bf16:6b22'
2022-03-19 08:01:31 ERROR (MainThread) [homeassistant.components.forecast_solar] Unexpected error fetching forecast_solar data: The Forecast.Solar API is unreachable, 
Traceback (most recent call last):
  File "/usr/src/homeassistant/homeassistant/helpers/update_coordinator.py", line 187, in _async_refresh
    self.data = await self._async_update_data()
  File "/usr/src/homeassistant/homeassistant/helpers/update_coordinator.py", line 147, in _async_update_data
    return await self.update_method()
  File "/usr/local/lib/python3.9/site-packages/forecast_solar/__init__.py", line 138, in estimate
    data = await self._request(
  File "/usr/local/lib/python3.9/site-packages/forecast_solar/__init__.py", line 105, in _request
    raise ForecastSolarConnectionError(
forecast_solar.exceptions.ForecastSolarConnectionError: The Forecast.Solar API is unreachable, 
2022-03-19 08:36:24 ERROR (MainThread) [homeassistant.components.ipp.coordinator] Error fetching ipp data: Invalid response from API: Timeout occurred while connecting to IPP server.
2022-03-19 09:51:29 ERROR (MainThread) [homeassistant.components.ipp.coordinator] Error fetching ipp data: Invalid response from API: Timeout occurred while connecting to IPP server.
2022-03-19 11:07:04 ERROR (MainThread) [homeassistant.components.forecast_solar] Unexpected error fetching forecast_solar data: The Forecast.Solar API is unreachable, 
Traceback (most recent call last):
  File "/usr/src/homeassistant/homeassistant/helpers/update_coordinator.py", line 187, in _async_refresh
    self.data = await self._async_update_data()
  File "/usr/src/homeassistant/homeassistant/helpers/update_coordinator.py", line 147, in _async_update_data
    return await self.update_method()
  File "/usr/local/lib/python3.9/site-packages/forecast_solar/__init__.py", line 138, in estimate
    data = await self._request(
  File "/usr/local/lib/python3.9/site-packages/forecast_solar/__init__.py", line 105, in _request
    raise ForecastSolarConnectionError(
forecast_solar.exceptions.ForecastSolarConnectionError: The Forecast.Solar API is unreachable, 
2022-03-19 11:32:00 ERROR (MainThread) [homeassistant.components.ipp.coordinator] Error fetching ipp data: Invalid response from API: Timeout occurred while connecting to IPP server.
2022-03-19 12:07:36 ERROR (MainThread) [homeassistant.components.forecast_solar] Unexpected error fetching forecast_solar data: The Forecast.Solar API is unreachable, 
Traceback (most recent call last):
  File "/usr/src/homeassistant/homeassistant/helpers/update_coordinator.py", line 187, in _async_refresh
    self.data = await self._async_update_data()
  File "/usr/src/homeassistant/homeassistant/helpers/update_coordinator.py", line 147, in _async_update_data
    return await self.update_method()
  File "/usr/local/lib/python3.9/site-packages/forecast_solar/__init__.py", line 138, in estimate
    data = await self._request(
  File "/usr/local/lib/python3.9/site-packages/forecast_solar/__init__.py", line 105, in _request
    raise ForecastSolarConnectionError(
forecast_solar.exceptions.ForecastSolarConnectionError: The Forecast.Solar API is unreachable, 
2022-03-19 13:06:53 ERROR (MainThread) [homeassistant.components.ipp.coordinator] Error fetching ipp data: Invalid response from API: Timeout occurred while connecting to IPP server.
2022-03-19 13:42:02 ERROR (MainThread) [homeassistant.components.ipp.coordinator] Error fetching ipp data: Invalid response from API: Timeout occurred while connecting to IPP server.
2022-03-19 15:36:16 ERROR (MainThread) [homeassistant.components.ipp.coordinator] Error fetching ipp data: Invalid response from API: Timeout occurred while connecting to IPP server.
2022-03-19 16:08:16 ERROR (MainThread) [homeassistant.components.forecast_solar] Unexpected error fetching forecast_solar data: The Forecast.Solar API is unreachable, 
Traceback (most recent call last):
  File "/usr/src/homeassistant/homeassistant/helpers/update_coordinator.py", line 187, in _async_refresh
    self.data = await self._async_update_data()
  File "/usr/src/homeassistant/homeassistant/helpers/update_coordinator.py", line 147, in _async_update_data
    return await self.update_method()
  File "/usr/local/lib/python3.9/site-packages/forecast_solar/__init__.py", line 138, in estimate
    data = await self._request(
  File "/usr/local/lib/python3.9/site-packages/forecast_solar/__init__.py", line 105, in _request
    raise ForecastSolarConnectionError(
forecast_solar.exceptions.ForecastSolarConnectionError: The Forecast.Solar API is unreachable, 
2022-03-19 16:52:28 ERROR (MainThread) [homeassistant.components.ipp.coordinator] Error fetching ipp data: Invalid response from API: Timeout occurred while connecting to IPP server.
2022-03-19 19:47:44 ERROR (MainThread) [homeassistant.components.ipp.coordinator] Error fetching ipp data: Invalid response from API: Timeout occurred while connecting to IPP server.
2022-03-19 20:43:21 ERROR (MainThread) [homeassistant.components.ipp.coordinator] Error fetching ipp data: Invalid response from API: Timeout occurred while connecting to IPP server.
2022-03-19 21:27:33 ERROR (MainThread) [homeassistant.components.ipp.coordinator] Error fetching ipp data: Invalid response from API: Timeout occurred while connecting to IPP server.
2022-03-19 21:52:22 ERROR (MainThread) [homeassistant.components.ipp.coordinator] Error fetching ipp data: Invalid response from API: Timeout occurred while connecting to IPP server.
2022-03-19 22:04:45 ERROR (MainThread) [homeassistant.components.ipp.coordinator] Error fetching ipp data: Invalid response from API: Timeout occurred while connecting to IPP server.
2022-03-19 23:54:55 ERROR (MainThread) [homeassistant.components.ipp.coordinator] Error fetching ipp data: Invalid response from API: Timeout occurred while connecting to IPP server.
2022-03-20 00:18:44 ERROR (MainThread) [homeassistant.components.ipp.coordinator] Error fetching ipp data: Invalid response from API: Timeout occurred while connecting to IPP server.
2022-03-20 01:23:49 ERROR (MainThread) [homeassistant.components.ipp.coordinator] Error fetching ipp data: Invalid response from API: Timeout occurred while connecting to IPP server.
2022-03-20 04:30:34 ERROR (MainThread) [homeassistant.components.ipp.coordinator] Error fetching ipp data: Invalid response from API: Timeout occurred while connecting to IPP server.
2022-03-20 05:54:45 ERROR (MainThread) [homeassistant.components.ipp.coordinator] Error fetching ipp data: Invalid response from API: Timeout occurred while connecting to IPP server.
2022-03-20 07:45:47 ERROR (MainThread) [homeassistant.components.ipp.coordinator] Error fetching ipp data: Invalid response from API: Timeout occurred while connecting to IPP server.
2022-03-20 09:36:04 ERROR (MainThread) [homeassistant.components.ipp.coordinator] Error fetching ipp data: Invalid response from API: Timeout occurred while connecting to IPP server.
2022-03-20 09:48:27 ERROR (MainThread) [homeassistant.components.ipp.coordinator] Error fetching ipp data: Invalid response from API: Timeout occurred while connecting to IPP server.
2022-03-20 10:31:46 ERROR (MainThread) [homeassistant.components.ipp.coordinator] Error fetching ipp data: Invalid response from API: Timeout occurred while connecting to IPP server.
2022-03-20 10:58:36 ERROR (MainThread) [homeassistant.components.ipp.coordinator] Error fetching ipp data: Invalid response from API: Timeout occurred while connecting to IPP server.
2022-03-20 11:28:45 ERROR (MainThread) [homeassistant.components.ipp.coordinator] Error fetching ipp data: Invalid response from API: Timeout occurred while connecting to IPP server.
2022-03-20 11:51:34 ERROR (MainThread) [homeassistant.components.ipp.coordinator] Error fetching ipp data: Invalid response from API: Timeout occurred while connecting to IPP server.
2022-03-20 13:26:36 ERROR (MainThread) [homeassistant.components.ipp.coordinator] Error fetching ipp data: Invalid response from API: Timeout occurred while connecting to IPP server.
2022-03-20 15:16:54 ERROR (MainThread) [homeassistant.components.ipp.coordinator] Error fetching ipp data: Invalid response from API: Timeout occurred while connecting to IPP server.
2022-03-20 17:02:15 ERROR (MainThread) [homeassistant.components.ipp.coordinator] Error fetching ipp data: Invalid response from API: Timeout occurred while connecting to IPP server.
2022-03-20 18:54:45 ERROR (MainThread) [homeassistant.components.ipp.coordinator] Error fetching ipp data: Invalid response from API: Timeout occurred while connecting to IPP server.
2022-03-20 21:37:55 ERROR (MainThread) [homeassistant.components.ipp.coordinator] Error fetching ipp data: Invalid response from API: Timeout occurred while connecting to IPP server.
2022-03-20 23:30:04 ERROR (MainThread) [homeassistant.components.speedtestdotnet] Error fetching speedtestdotnet data: Unable to connect to servers to test latency.
2022-03-21 06:25:26 ERROR (MainThread) [homeassistant.components.ipp.coordinator] Error fetching ipp data: Invalid response from API: Timeout occurred while connecting to IPP server.
2022-03-21 06:36:05 ERROR (MainThread) [homeassistant.components.apple_tv.config_flow] Unexpected exception
Traceback (most recent call last):
  File "/usr/src/homeassistant/homeassistant/components/apple_tv/config_flow.py", line 270, in async_find_device_wrapper
    await self.async_find_device(allow_exist)
  File "/usr/src/homeassistant/homeassistant/components/apple_tv/config_flow.py", line 283, in async_find_device
    self.atv, self.atv_identifiers = await device_scan(
  File "/usr/src/homeassistant/homeassistant/components/apple_tv/config_flow.py", line 57, in device_scan
    scan_result = await scan(loop, timeout=3, hosts=_host_filter(), aiozc=aiozc)
  File "/usr/local/lib/python3.9/site-packages/pyatv/__init__.py", line 58, in scan
    aiozc, hosts=[IPv4Address(host) for host in hosts]
  File "/usr/local/lib/python3.9/site-packages/pyatv/__init__.py", line 58, in <listcomp>
    aiozc, hosts=[IPv4Address(host) for host in hosts]
  File "/usr/local/lib/python3.9/ipaddress.py", line 1307, in __init__
    self._ip = self._ip_int_from_string(addr_str)
  File "/usr/local/lib/python3.9/ipaddress.py", line 1194, in _ip_int_from_string
    raise AddressValueError("Expected 4 octets in %r" % ip_str)
ipaddress.AddressValueError: Expected 4 octets in '2c0f:f4c0:118c:40e0:db:f108:bf16:6b22'
