2022-03-30 08:01:29 WARNING (SyncWorker_0) [homeassistant.loader] We found a custom integration eskom_loadshedding which has not been tested by Home Assistant. This component might cause stability problems, be sure to disable it if you experience issues with Home Assistant
2022-03-30 08:01:29 WARNING (SyncWorker_1) [homeassistant.loader] We found a custom integration sonoff which has not been tested by Home Assistant. This component might cause stability problems, be sure to disable it if you experience issues with Home Assistant
2022-03-30 08:01:29 WARNING (SyncWorker_0) [homeassistant.loader] We found a custom integration hacs which has not been tested by Home Assistant. This component might cause stability problems, be sure to disable it if you experience issues with Home Assistant
2022-03-30 08:01:37 WARNING (Recorder) [homeassistant.components.recorder.util] Ended unfinished session (id=63 from 2022-03-24 14:07:25)
2022-03-30 08:01:52 WARNING (MainThread) [homeassistant.setup] Setup of hassio is taking over 10 seconds.
2022-03-30 08:02:03 WARNING (MainThread) [homeassistant.helpers.entity] Entity sensor.eskom_loadshedding_stage (<class 'custom_components.eskom_loadshedding.sensor.EskomStageSensor'>) implements device_state_attributes. Please report it to the custom component author.
2022-03-30 08:02:06 WARNING (MainThread) [homeassistant.components.konnected.panel] Exception trying to connect to panel: Cannot connect to host 192.168.0.211:9939 ssl:default [Connect call failed ('192.168.0.211', 9939)]
2022-03-30 08:02:11 WARNING (MainThread) [homeassistant.components.konnected.panel] Exception trying to connect to panel: 
2022-03-30 08:02:33 WARNING (MainThread) [homeassistant.components.konnected.panel] Exception trying to connect to panel: 
2022-03-30 08:02:33 WARNING (MainThread) [homeassistant.components.konnected.panel] Exception trying to connect to panel: 
2022-03-30 11:06:26 ERROR (MainThread) [homeassistant.components.ipp.coordinator] Error fetching ipp data: Invalid response from API: Timeout occurred while connecting to IPP server.
2022-03-30 15:05:46 ERROR (MainThread) [homeassistant.components.ipp.coordinator] Error fetching ipp data: Invalid response from API: Timeout occurred while connecting to IPP server.
2022-03-30 15:19:12 ERROR (MainThread) [homeassistant.components.ipp.coordinator] Error fetching ipp data: Invalid response from API: Timeout occurred while connecting to IPP server.
2022-03-30 15:30:16 ERROR (MainThread) [metno] Access to https://aa015h6buqvih86i1.api.met.no/weatherapi/locationforecast/2.0/complete returned error 'ClientConnectorError'
2022-03-30 15:48:54 ERROR (MainThread) [custom_components.eskom_loadshedding] Error fetching eskom_loadshedding data: Cannot connect to host loadshedding.eskom.co.za:443 ssl:<ssl.SSLContext object at 0x7f93bbaf4740> [Try again]
2022-03-30 15:57:46 ERROR (MainThread) [async_upnp_client.ssdp] Received error: [Errno 101] Network unreachable, transport: <_SelectorDatagramTransport fd=15 read=polling write=<idle, bufsize=0>>
2022-03-30 15:57:46 ERROR (MainThread) [async_upnp_client.ssdp] Received error: [Errno 101] Network unreachable, transport: <_SelectorDatagramTransport fd=15 read=polling write=<idle, bufsize=0>>
2022-03-30 15:58:17 WARNING (MainThread) [zeroconf] Error with socket 11 (('192.168.0.200', 5353))): [Errno 101] Network unreachable
Traceback (most recent call last):
  File "/usr/local/lib/python3.9/asyncio/selector_events.py", line 1056, in sendto
    self._sock.sendto(data, addr)
OSError: [Errno 101] Network unreachable
2022-03-30 15:59:46 ERROR (MainThread) [async_upnp_client.ssdp] Received error: [Errno 101] Network unreachable, transport: <_SelectorDatagramTransport fd=15 read=polling write=<idle, bufsize=0>>
2022-03-30 15:59:46 ERROR (MainThread) [async_upnp_client.ssdp] Received error: [Errno 101] Network unreachable, transport: <_SelectorDatagramTransport fd=15 read=polling write=<idle, bufsize=0>>
2022-03-30 16:01:46 ERROR (MainThread) [async_upnp_client.ssdp] Received error: [Errno 101] Network unreachable, transport: <_SelectorDatagramTransport fd=15 read=polling write=<idle, bufsize=0>>
2022-03-30 16:01:46 ERROR (MainThread) [async_upnp_client.ssdp] Received error: [Errno 101] Network unreachable, transport: <_SelectorDatagramTransport fd=15 read=polling write=<idle, bufsize=0>>
2022-03-30 16:02:08 ERROR (MainThread) [custom_components.hacs] Request exception for 'https://api.github.com/rate_limit' with - Cannot connect to host api.github.com:443 ssl:default [Try again]
Traceback (most recent call last):
  File "/config/custom_components/hacs/base.py", line 427, in async_can_update
    response = await self.async_github_api_method(self.githubapi.rate_limit)
  File "/config/custom_components/hacs/base.py", line 478, in async_github_api_method
    raise HacsException(_exception)
custom_components.hacs.exceptions.HacsException: Request exception for 'https://api.github.com/rate_limit' with - Cannot connect to host api.github.com:443 ssl:default [Try again]
2022-03-30 16:02:14 ERROR (MainThread) [homeassistant.components.forecast_solar] Unexpected error fetching forecast_solar data: Error while resolving Forecast.Solar API address
Traceback (most recent call last):
  File "/usr/local/lib/python3.9/site-packages/forecast_solar/__init__.py", line 72, in _request
    result = await dns.query("api.forecast.solar", "A")
aiodns.error.DNSError: (11, 'Could not contact DNS servers')

The above exception was the direct cause of the following exception:

Traceback (most recent call last):
  File "/usr/src/homeassistant/homeassistant/helpers/update_coordinator.py", line 187, in _async_refresh
    self.data = await self._async_update_data()
  File "/usr/src/homeassistant/homeassistant/helpers/update_coordinator.py", line 147, in _async_update_data
    return await self.update_method()
  File "/usr/local/lib/python3.9/site-packages/forecast_solar/__init__.py", line 138, in estimate
    data = await self._request(
  File "/usr/local/lib/python3.9/site-packages/forecast_solar/__init__.py", line 74, in _request
    raise ForecastSolarConnectionError(
forecast_solar.exceptions.ForecastSolarConnectionError: Error while resolving Forecast.Solar API address
2022-03-30 16:02:30 ERROR (MainThread) [custom_components.hacs] <Integration AlexxIT/SonoffLAN> Cannot connect to host api.github.com:443 ssl:default [Try again]
2022-03-30 16:02:30 ERROR (MainThread) [custom_components.hacs] <Integration hacs/integration> Cannot connect to host api.github.com:443 ssl:default [Try again]
2022-03-30 16:03:46 ERROR (MainThread) [async_upnp_client.ssdp] Received error: [Errno 101] Network unreachable, transport: <_SelectorDatagramTransport fd=15 read=polling write=<idle, bufsize=0>>
2022-03-30 16:03:46 ERROR (MainThread) [async_upnp_client.ssdp] Received error: [Errno 101] Network unreachable, transport: <_SelectorDatagramTransport fd=15 read=polling write=<idle, bufsize=0>>
2022-03-30 16:05:46 ERROR (MainThread) [async_upnp_client.ssdp] Received error: [Errno 101] Network unreachable, transport: <_SelectorDatagramTransport fd=15 read=polling write=<idle, bufsize=0>>
2022-03-30 16:05:46 ERROR (MainThread) [async_upnp_client.ssdp] Received error: [Errno 101] Network unreachable, transport: <_SelectorDatagramTransport fd=15 read=polling write=<idle, bufsize=0>>
2022-03-30 16:07:46 ERROR (MainThread) [async_upnp_client.ssdp] Received error: [Errno 101] Network unreachable, transport: <_SelectorDatagramTransport fd=15 read=polling write=<idle, bufsize=0>>
2022-03-30 16:07:46 ERROR (MainThread) [async_upnp_client.ssdp] Received error: [Errno 101] Network unreachable, transport: <_SelectorDatagramTransport fd=15 read=polling write=<idle, bufsize=0>>
2022-03-30 16:07:59 ERROR (MainThread) [homeassistant.components.speedtestdotnet] Error fetching speedtestdotnet data: Unable to connect to servers to test latency.
2022-03-30 16:09:46 ERROR (MainThread) [async_upnp_client.ssdp] Received error: [Errno 101] Network unreachable, transport: <_SelectorDatagramTransport fd=15 read=polling write=<idle, bufsize=0>>
2022-03-30 16:09:46 ERROR (MainThread) [async_upnp_client.ssdp] Received error: [Errno 101] Network unreachable, transport: <_SelectorDatagramTransport fd=15 read=polling write=<idle, bufsize=0>>
2022-03-30 16:11:46 ERROR (MainThread) [async_upnp_client.ssdp] Received error: [Errno 101] Network unreachable, transport: <_SelectorDatagramTransport fd=15 read=polling write=<idle, bufsize=0>>
2022-03-30 16:11:46 ERROR (MainThread) [async_upnp_client.ssdp] Received error: [Errno 101] Network unreachable, transport: <_SelectorDatagramTransport fd=15 read=polling write=<idle, bufsize=0>>
2022-03-30 16:12:08 ERROR (MainThread) [custom_components.hacs] Request exception for 'https://api.github.com/rate_limit' with - Cannot connect to host api.github.com:443 ssl:default [Try again]
Traceback (most recent call last):
  File "/config/custom_components/hacs/base.py", line 427, in async_can_update
    response = await self.async_github_api_method(self.githubapi.rate_limit)
  File "/config/custom_components/hacs/base.py", line 478, in async_github_api_method
    raise HacsException(_exception)
custom_components.hacs.exceptions.HacsException: Request exception for 'https://api.github.com/rate_limit' with - Cannot connect to host api.github.com:443 ssl:default [Try again]
2022-03-30 16:13:46 ERROR (MainThread) [async_upnp_client.ssdp] Received error: [Errno 101] Network unreachable, transport: <_SelectorDatagramTransport fd=15 read=polling write=<idle, bufsize=0>>
2022-03-30 16:13:46 ERROR (MainThread) [async_upnp_client.ssdp] Received error: [Errno 101] Network unreachable, transport: <_SelectorDatagramTransport fd=15 read=polling write=<idle, bufsize=0>>
2022-03-30 16:15:46 ERROR (MainThread) [async_upnp_client.ssdp] Received error: [Errno 101] Network unreachable, transport: <_SelectorDatagramTransport fd=15 read=polling write=<idle, bufsize=0>>
2022-03-30 16:15:46 ERROR (MainThread) [async_upnp_client.ssdp] Received error: [Errno 101] Network unreachable, transport: <_SelectorDatagramTransport fd=15 read=polling write=<idle, bufsize=0>>
2022-03-30 16:17:46 ERROR (MainThread) [async_upnp_client.ssdp] Received error: [Errno 101] Network unreachable, transport: <_SelectorDatagramTransport fd=15 read=polling write=<idle, bufsize=0>>
2022-03-30 16:17:46 ERROR (MainThread) [async_upnp_client.ssdp] Received error: [Errno 101] Network unreachable, transport: <_SelectorDatagramTransport fd=15 read=polling write=<idle, bufsize=0>>
2022-03-30 16:19:46 ERROR (MainThread) [async_upnp_client.ssdp] Received error: [Errno 101] Network unreachable, transport: <_SelectorDatagramTransport fd=15 read=polling write=<idle, bufsize=0>>
2022-03-30 16:19:46 ERROR (MainThread) [async_upnp_client.ssdp] Received error: [Errno 101] Network unreachable, transport: <_SelectorDatagramTransport fd=15 read=polling write=<idle, bufsize=0>>
2022-03-30 16:21:46 ERROR (MainThread) [async_upnp_client.ssdp] Received error: [Errno 101] Network unreachable, transport: <_SelectorDatagramTransport fd=15 read=polling write=<idle, bufsize=0>>
2022-03-30 16:21:46 ERROR (MainThread) [async_upnp_client.ssdp] Received error: [Errno 101] Network unreachable, transport: <_SelectorDatagramTransport fd=15 read=polling write=<idle, bufsize=0>>
2022-03-30 16:22:08 ERROR (MainThread) [custom_components.hacs] Request exception for 'https://api.github.com/rate_limit' with - Cannot connect to host api.github.com:443 ssl:default [Try again]
Traceback (most recent call last):
  File "/config/custom_components/hacs/base.py", line 427, in async_can_update
    response = await self.async_github_api_method(self.githubapi.rate_limit)
  File "/config/custom_components/hacs/base.py", line 478, in async_github_api_method
    raise HacsException(_exception)
custom_components.hacs.exceptions.HacsException: Request exception for 'https://api.github.com/rate_limit' with - Cannot connect to host api.github.com:443 ssl:default [Try again]
2022-03-30 16:23:46 ERROR (MainThread) [async_upnp_client.ssdp] Received error: [Errno 101] Network unreachable, transport: <_SelectorDatagramTransport fd=15 read=polling write=<idle, bufsize=0>>
2022-03-30 16:23:46 ERROR (MainThread) [async_upnp_client.ssdp] Received error: [Errno 101] Network unreachable, transport: <_SelectorDatagramTransport fd=15 read=polling write=<idle, bufsize=0>>
2022-03-30 16:25:46 ERROR (MainThread) [async_upnp_client.ssdp] Received error: [Errno 101] Network unreachable, transport: <_SelectorDatagramTransport fd=15 read=polling write=<idle, bufsize=0>>
2022-03-30 16:25:46 ERROR (MainThread) [async_upnp_client.ssdp] Received error: [Errno 101] Network unreachable, transport: <_SelectorDatagramTransport fd=15 read=polling write=<idle, bufsize=0>>
2022-03-30 16:26:21 ERROR (MainThread) [metno] Access to https://aa015h6buqvih86i1.api.met.no/weatherapi/locationforecast/2.0/complete returned error 'ClientConnectorError'
2022-03-30 16:27:46 ERROR (MainThread) [async_upnp_client.ssdp] Received error: [Errno 101] Network unreachable, transport: <_SelectorDatagramTransport fd=15 read=polling write=<idle, bufsize=0>>
2022-03-30 16:27:46 ERROR (MainThread) [async_upnp_client.ssdp] Received error: [Errno 101] Network unreachable, transport: <_SelectorDatagramTransport fd=15 read=polling write=<idle, bufsize=0>>
2022-03-30 16:29:46 ERROR (MainThread) [async_upnp_client.ssdp] Received error: [Errno 101] Network unreachable, transport: <_SelectorDatagramTransport fd=15 read=polling write=<idle, bufsize=0>>
2022-03-30 16:29:46 ERROR (MainThread) [async_upnp_client.ssdp] Received error: [Errno 101] Network unreachable, transport: <_SelectorDatagramTransport fd=15 read=polling write=<idle, bufsize=0>>
2022-03-30 16:31:46 ERROR (MainThread) [async_upnp_client.ssdp] Received error: [Errno 101] Network unreachable, transport: <_SelectorDatagramTransport fd=15 read=polling write=<idle, bufsize=0>>
2022-03-30 16:31:46 ERROR (MainThread) [async_upnp_client.ssdp] Received error: [Errno 101] Network unreachable, transport: <_SelectorDatagramTransport fd=15 read=polling write=<idle, bufsize=0>>
2022-03-30 16:32:08 ERROR (MainThread) [custom_components.hacs] Request exception for 'https://api.github.com/rate_limit' with - Cannot connect to host api.github.com:443 ssl:default [Try again]
Traceback (most recent call last):
  File "/config/custom_components/hacs/base.py", line 427, in async_can_update
    response = await self.async_github_api_method(self.githubapi.rate_limit)
  File "/config/custom_components/hacs/base.py", line 478, in async_github_api_method
    raise HacsException(_exception)
custom_components.hacs.exceptions.HacsException: Request exception for 'https://api.github.com/rate_limit' with - Cannot connect to host api.github.com:443 ssl:default [Try again]
2022-03-30 16:33:46 ERROR (MainThread) [async_upnp_client.ssdp] Received error: [Errno 101] Network unreachable, transport: <_SelectorDatagramTransport fd=15 read=polling write=<idle, bufsize=0>>
2022-03-30 16:33:46 ERROR (MainThread) [async_upnp_client.ssdp] Received error: [Errno 101] Network unreachable, transport: <_SelectorDatagramTransport fd=15 read=polling write=<idle, bufsize=0>>
2022-03-30 16:35:46 ERROR (MainThread) [async_upnp_client.ssdp] Received error: [Errno 101] Network unreachable, transport: <_SelectorDatagramTransport fd=15 read=polling write=<idle, bufsize=0>>
2022-03-30 16:35:46 ERROR (MainThread) [async_upnp_client.ssdp] Received error: [Errno 101] Network unreachable, transport: <_SelectorDatagramTransport fd=15 read=polling write=<idle, bufsize=0>>
2022-03-30 16:37:46 ERROR (MainThread) [async_upnp_client.ssdp] Received error: [Errno 101] Network unreachable, transport: <_SelectorDatagramTransport fd=15 read=polling write=<idle, bufsize=0>>
2022-03-30 16:37:46 ERROR (MainThread) [async_upnp_client.ssdp] Received error: [Errno 101] Network unreachable, transport: <_SelectorDatagramTransport fd=15 read=polling write=<idle, bufsize=0>>
2022-03-30 16:39:46 ERROR (MainThread) [async_upnp_client.ssdp] Received error: [Errno 101] Network unreachable, transport: <_SelectorDatagramTransport fd=15 read=polling write=<idle, bufsize=0>>
2022-03-30 16:39:46 ERROR (MainThread) [async_upnp_client.ssdp] Received error: [Errno 101] Network unreachable, transport: <_SelectorDatagramTransport fd=15 read=polling write=<idle, bufsize=0>>
2022-03-30 16:41:46 ERROR (MainThread) [async_upnp_client.ssdp] Received error: [Errno 101] Network unreachable, transport: <_SelectorDatagramTransport fd=15 read=polling write=<idle, bufsize=0>>
2022-03-30 16:41:46 ERROR (MainThread) [async_upnp_client.ssdp] Received error: [Errno 101] Network unreachable, transport: <_SelectorDatagramTransport fd=15 read=polling write=<idle, bufsize=0>>
2022-03-30 16:42:08 ERROR (MainThread) [custom_components.hacs] Request exception for 'https://api.github.com/rate_limit' with - Cannot connect to host api.github.com:443 ssl:default [Try again]
Traceback (most recent call last):
  File "/config/custom_components/hacs/base.py", line 427, in async_can_update
    response = await self.async_github_api_method(self.githubapi.rate_limit)
  File "/config/custom_components/hacs/base.py", line 478, in async_github_api_method
    raise HacsException(_exception)
custom_components.hacs.exceptions.HacsException: Request exception for 'https://api.github.com/rate_limit' with - Cannot connect to host api.github.com:443 ssl:default [Try again]
2022-03-30 16:43:46 ERROR (MainThread) [async_upnp_client.ssdp] Received error: [Errno 101] Network unreachable, transport: <_SelectorDatagramTransport fd=15 read=polling write=<idle, bufsize=0>>
2022-03-30 16:43:46 ERROR (MainThread) [async_upnp_client.ssdp] Received error: [Errno 101] Network unreachable, transport: <_SelectorDatagramTransport fd=15 read=polling write=<idle, bufsize=0>>
2022-03-30 16:45:46 ERROR (MainThread) [async_upnp_client.ssdp] Received error: [Errno 101] Network unreachable, transport: <_SelectorDatagramTransport fd=15 read=polling write=<idle, bufsize=0>>
2022-03-30 16:45:46 ERROR (MainThread) [async_upnp_client.ssdp] Received error: [Errno 101] Network unreachable, transport: <_SelectorDatagramTransport fd=15 read=polling write=<idle, bufsize=0>>
2022-03-30 16:47:46 ERROR (MainThread) [async_upnp_client.ssdp] Received error: [Errno 101] Network unreachable, transport: <_SelectorDatagramTransport fd=15 read=polling write=<idle, bufsize=0>>
2022-03-30 16:47:46 ERROR (MainThread) [async_upnp_client.ssdp] Received error: [Errno 101] Network unreachable, transport: <_SelectorDatagramTransport fd=15 read=polling write=<idle, bufsize=0>>
2022-03-30 16:49:46 ERROR (MainThread) [async_upnp_client.ssdp] Received error: [Errno 101] Network unreachable, transport: <_SelectorDatagramTransport fd=15 read=polling write=<idle, bufsize=0>>
2022-03-30 16:49:46 ERROR (MainThread) [async_upnp_client.ssdp] Received error: [Errno 101] Network unreachable, transport: <_SelectorDatagramTransport fd=15 read=polling write=<idle, bufsize=0>>
2022-03-30 16:51:46 ERROR (MainThread) [async_upnp_client.ssdp] Received error: [Errno 101] Network unreachable, transport: <_SelectorDatagramTransport fd=15 read=polling write=<idle, bufsize=0>>
2022-03-30 16:51:46 ERROR (MainThread) [async_upnp_client.ssdp] Received error: [Errno 101] Network unreachable, transport: <_SelectorDatagramTransport fd=15 read=polling write=<idle, bufsize=0>>
2022-03-30 16:52:08 ERROR (MainThread) [custom_components.hacs] Request exception for 'https://api.github.com/rate_limit' with - Cannot connect to host api.github.com:443 ssl:default [Try again]
Traceback (most recent call last):
  File "/config/custom_components/hacs/base.py", line 427, in async_can_update
    response = await self.async_github_api_method(self.githubapi.rate_limit)
  File "/config/custom_components/hacs/base.py", line 478, in async_github_api_method
    raise HacsException(_exception)
custom_components.hacs.exceptions.HacsException: Request exception for 'https://api.github.com/rate_limit' with - Cannot connect to host api.github.com:443 ssl:default [Try again]
2022-03-30 16:53:46 ERROR (MainThread) [async_upnp_client.ssdp] Received error: [Errno 101] Network unreachable, transport: <_SelectorDatagramTransport fd=15 read=polling write=<idle, bufsize=0>>
2022-03-30 16:53:46 ERROR (MainThread) [async_upnp_client.ssdp] Received error: [Errno 101] Network unreachable, transport: <_SelectorDatagramTransport fd=15 read=polling write=<idle, bufsize=0>>
2022-03-30 16:55:46 ERROR (MainThread) [async_upnp_client.ssdp] Received error: [Errno 101] Network unreachable, transport: <_SelectorDatagramTransport fd=15 read=polling write=<idle, bufsize=0>>
2022-03-30 16:55:46 ERROR (MainThread) [async_upnp_client.ssdp] Received error: [Errno 101] Network unreachable, transport: <_SelectorDatagramTransport fd=15 read=polling write=<idle, bufsize=0>>
2022-03-30 16:57:46 ERROR (MainThread) [async_upnp_client.ssdp] Received error: [Errno 101] Network unreachable, transport: <_SelectorDatagramTransport fd=15 read=polling write=<idle, bufsize=0>>
2022-03-30 16:57:46 ERROR (MainThread) [async_upnp_client.ssdp] Received error: [Errno 101] Network unreachable, transport: <_SelectorDatagramTransport fd=15 read=polling write=<idle, bufsize=0>>
2022-03-30 16:59:46 ERROR (MainThread) [async_upnp_client.ssdp] Received error: [Errno 101] Network unreachable, transport: <_SelectorDatagramTransport fd=15 read=polling write=<idle, bufsize=0>>
2022-03-30 16:59:46 ERROR (MainThread) [async_upnp_client.ssdp] Received error: [Errno 101] Network unreachable, transport: <_SelectorDatagramTransport fd=15 read=polling write=<idle, bufsize=0>>
2022-03-30 17:01:46 ERROR (MainThread) [async_upnp_client.ssdp] Received error: [Errno 101] Network unreachable, transport: <_SelectorDatagramTransport fd=15 read=polling write=<idle, bufsize=0>>
2022-03-30 17:01:46 ERROR (MainThread) [async_upnp_client.ssdp] Received error: [Errno 101] Network unreachable, transport: <_SelectorDatagramTransport fd=15 read=polling write=<idle, bufsize=0>>
2022-03-30 17:02:08 ERROR (MainThread) [custom_components.hacs] Request exception for 'https://api.github.com/rate_limit' with - Cannot connect to host api.github.com:443 ssl:default [Try again]
Traceback (most recent call last):
  File "/config/custom_components/hacs/base.py", line 427, in async_can_update
    response = await self.async_github_api_method(self.githubapi.rate_limit)
  File "/config/custom_components/hacs/base.py", line 478, in async_github_api_method
    raise HacsException(_exception)
custom_components.hacs.exceptions.HacsException: Request exception for 'https://api.github.com/rate_limit' with - Cannot connect to host api.github.com:443 ssl:default [Try again]
2022-03-30 17:02:14 ERROR (MainThread) [homeassistant.components.forecast_solar] Unexpected error fetching forecast_solar data: Error while resolving Forecast.Solar API address
Traceback (most recent call last):
  File "/usr/local/lib/python3.9/site-packages/forecast_solar/__init__.py", line 72, in _request
    result = await dns.query("api.forecast.solar", "A")
aiodns.error.DNSError: (11, 'Could not contact DNS servers')

The above exception was the direct cause of the following exception:

Traceback (most recent call last):
  File "/usr/src/homeassistant/homeassistant/helpers/update_coordinator.py", line 187, in _async_refresh
    self.data = await self._async_update_data()
  File "/usr/src/homeassistant/homeassistant/helpers/update_coordinator.py", line 147, in _async_update_data
    return await self.update_method()
  File "/usr/local/lib/python3.9/site-packages/forecast_solar/__init__.py", line 138, in estimate
    data = await self._request(
  File "/usr/local/lib/python3.9/site-packages/forecast_solar/__init__.py", line 74, in _request
    raise ForecastSolarConnectionError(
forecast_solar.exceptions.ForecastSolarConnectionError: Error while resolving Forecast.Solar API address
2022-03-30 17:02:23 ERROR (MainThread) [homeassistant] Error doing job: Task exception was never retrieved
Traceback (most recent call last):
  File "/usr/src/homeassistant/homeassistant/components/dhcp/__init__.py", line 287, in async_discover
    for host in await self._discover_hosts.async_discover():
  File "/usr/local/lib/python3.9/site-packages/aiodiscover/discovery.py", line 143, in async_discover
    sys_network_data = await loop.run_in_executor(None, self._get_sys_network_data)
  File "/usr/local/lib/python3.9/concurrent/futures/thread.py", line 58, in run
    result = self.fn(*self.args, **self.kwargs)
  File "/usr/local/lib/python3.9/site-packages/aiodiscover/discovery.py", line 137, in _get_sys_network_data
    sys_network_data.setup()
  File "/usr/local/lib/python3.9/site-packages/aiodiscover/network.py", line 155, in setup
    self.network = get_network(self.local_ip, self.adapters)
  File "/usr/local/lib/python3.9/site-packages/aiodiscover/network.py", line 74, in get_network
    return ip_network(f"{local_ip}/{network_prefix}", False)
  File "/usr/local/lib/python3.9/ipaddress.py", line 83, in ip_network
    raise ValueError('%r does not appear to be an IPv4 or IPv6 network' %
ValueError: 'None/24' does not appear to be an IPv4 or IPv6 network
2022-03-30 17:03:46 ERROR (MainThread) [async_upnp_client.ssdp] Received error: [Errno 101] Network unreachable, transport: <_SelectorDatagramTransport fd=15 read=polling write=<idle, bufsize=0>>
2022-03-30 17:03:46 ERROR (MainThread) [async_upnp_client.ssdp] Received error: [Errno 101] Network unreachable, transport: <_SelectorDatagramTransport fd=15 read=polling write=<idle, bufsize=0>>
2022-03-30 17:05:46 ERROR (MainThread) [async_upnp_client.ssdp] Received error: [Errno 101] Network unreachable, transport: <_SelectorDatagramTransport fd=15 read=polling write=<idle, bufsize=0>>
2022-03-30 17:05:46 ERROR (MainThread) [async_upnp_client.ssdp] Received error: [Errno 101] Network unreachable, transport: <_SelectorDatagramTransport fd=15 read=polling write=<idle, bufsize=0>>
2022-03-30 17:07:46 ERROR (MainThread) [async_upnp_client.ssdp] Received error: [Errno 101] Network unreachable, transport: <_SelectorDatagramTransport fd=15 read=polling write=<idle, bufsize=0>>
2022-03-30 17:07:46 ERROR (MainThread) [async_upnp_client.ssdp] Received error: [Errno 101] Network unreachable, transport: <_SelectorDatagramTransport fd=15 read=polling write=<idle, bufsize=0>>
2022-03-30 17:09:46 ERROR (MainThread) [async_upnp_client.ssdp] Received error: [Errno 101] Network unreachable, transport: <_SelectorDatagramTransport fd=15 read=polling write=<idle, bufsize=0>>
2022-03-30 17:09:46 ERROR (MainThread) [async_upnp_client.ssdp] Received error: [Errno 101] Network unreachable, transport: <_SelectorDatagramTransport fd=15 read=polling write=<idle, bufsize=0>>
2022-03-30 17:11:46 ERROR (MainThread) [async_upnp_client.ssdp] Received error: [Errno 101] Network unreachable, transport: <_SelectorDatagramTransport fd=15 read=polling write=<idle, bufsize=0>>
2022-03-30 17:11:46 ERROR (MainThread) [async_upnp_client.ssdp] Received error: [Errno 101] Network unreachable, transport: <_SelectorDatagramTransport fd=15 read=polling write=<idle, bufsize=0>>
2022-03-30 17:12:08 ERROR (MainThread) [custom_components.hacs] Request exception for 'https://api.github.com/rate_limit' with - Cannot connect to host api.github.com:443 ssl:default [Try again]
Traceback (most recent call last):
  File "/config/custom_components/hacs/base.py", line 427, in async_can_update
    response = await self.async_github_api_method(self.githubapi.rate_limit)
  File "/config/custom_components/hacs/base.py", line 478, in async_github_api_method
    raise HacsException(_exception)
custom_components.hacs.exceptions.HacsException: Request exception for 'https://api.github.com/rate_limit' with - Cannot connect to host api.github.com:443 ssl:default [Try again]
2022-03-30 17:13:46 ERROR (MainThread) [async_upnp_client.ssdp] Received error: [Errno 101] Network unreachable, transport: <_SelectorDatagramTransport fd=15 read=polling write=<idle, bufsize=0>>
2022-03-30 17:13:46 ERROR (MainThread) [async_upnp_client.ssdp] Received error: [Errno 101] Network unreachable, transport: <_SelectorDatagramTransport fd=15 read=polling write=<idle, bufsize=0>>
2022-03-30 17:15:46 ERROR (MainThread) [async_upnp_client.ssdp] Received error: [Errno 101] Network unreachable, transport: <_SelectorDatagramTransport fd=15 read=polling write=<idle, bufsize=0>>
2022-03-30 17:15:46 ERROR (MainThread) [async_upnp_client.ssdp] Received error: [Errno 101] Network unreachable, transport: <_SelectorDatagramTransport fd=15 read=polling write=<idle, bufsize=0>>
2022-03-30 17:17:46 ERROR (MainThread) [async_upnp_client.ssdp] Received error: [Errno 101] Network unreachable, transport: <_SelectorDatagramTransport fd=15 read=polling write=<idle, bufsize=0>>
2022-03-30 17:17:46 ERROR (MainThread) [async_upnp_client.ssdp] Received error: [Errno 101] Network unreachable, transport: <_SelectorDatagramTransport fd=15 read=polling write=<idle, bufsize=0>>
2022-03-30 17:19:46 ERROR (MainThread) [async_upnp_client.ssdp] Received error: [Errno 101] Network unreachable, transport: <_SelectorDatagramTransport fd=15 read=polling write=<idle, bufsize=0>>
2022-03-30 17:19:46 ERROR (MainThread) [async_upnp_client.ssdp] Received error: [Errno 101] Network unreachable, transport: <_SelectorDatagramTransport fd=15 read=polling write=<idle, bufsize=0>>
2022-03-30 17:21:46 ERROR (MainThread) [async_upnp_client.ssdp] Received error: [Errno 101] Network unreachable, transport: <_SelectorDatagramTransport fd=15 read=polling write=<idle, bufsize=0>>
2022-03-30 17:21:46 ERROR (MainThread) [async_upnp_client.ssdp] Received error: [Errno 101] Network unreachable, transport: <_SelectorDatagramTransport fd=15 read=polling write=<idle, bufsize=0>>
2022-03-30 17:22:08 ERROR (MainThread) [custom_components.hacs] Request exception for 'https://api.github.com/rate_limit' with - Cannot connect to host api.github.com:443 ssl:default [Try again]
Traceback (most recent call last):
  File "/config/custom_components/hacs/base.py", line 427, in async_can_update
    response = await self.async_github_api_method(self.githubapi.rate_limit)
  File "/config/custom_components/hacs/base.py", line 478, in async_github_api_method
    raise HacsException(_exception)
custom_components.hacs.exceptions.HacsException: Request exception for 'https://api.github.com/rate_limit' with - Cannot connect to host api.github.com:443 ssl:default [Try again]
2022-03-30 17:22:26 ERROR (MainThread) [metno] Access to https://aa015h6buqvih86i1.api.met.no/weatherapi/locationforecast/2.0/complete returned error 'ClientConnectorError'
2022-03-30 17:23:46 ERROR (MainThread) [async_upnp_client.ssdp] Received error: [Errno 101] Network unreachable, transport: <_SelectorDatagramTransport fd=15 read=polling write=<idle, bufsize=0>>
2022-03-30 17:23:46 ERROR (MainThread) [async_upnp_client.ssdp] Received error: [Errno 101] Network unreachable, transport: <_SelectorDatagramTransport fd=15 read=polling write=<idle, bufsize=0>>
2022-03-30 17:25:46 ERROR (MainThread) [async_upnp_client.ssdp] Received error: [Errno 101] Network unreachable, transport: <_SelectorDatagramTransport fd=15 read=polling write=<idle, bufsize=0>>
2022-03-30 17:25:46 ERROR (MainThread) [async_upnp_client.ssdp] Received error: [Errno 101] Network unreachable, transport: <_SelectorDatagramTransport fd=15 read=polling write=<idle, bufsize=0>>
2022-03-30 17:27:46 ERROR (MainThread) [async_upnp_client.ssdp] Received error: [Errno 101] Network unreachable, transport: <_SelectorDatagramTransport fd=15 read=polling write=<idle, bufsize=0>>
2022-03-30 17:27:46 ERROR (MainThread) [async_upnp_client.ssdp] Received error: [Errno 101] Network unreachable, transport: <_SelectorDatagramTransport fd=15 read=polling write=<idle, bufsize=0>>
2022-03-30 17:29:46 ERROR (MainThread) [async_upnp_client.ssdp] Received error: [Errno 101] Network unreachable, transport: <_SelectorDatagramTransport fd=15 read=polling write=<idle, bufsize=0>>
2022-03-30 17:29:46 ERROR (MainThread) [async_upnp_client.ssdp] Received error: [Errno 101] Network unreachable, transport: <_SelectorDatagramTransport fd=15 read=polling write=<idle, bufsize=0>>
2022-03-30 17:31:46 ERROR (MainThread) [async_upnp_client.ssdp] Received error: [Errno 101] Network unreachable, transport: <_SelectorDatagramTransport fd=15 read=polling write=<idle, bufsize=0>>
2022-03-30 17:31:46 ERROR (MainThread) [async_upnp_client.ssdp] Received error: [Errno 101] Network unreachable, transport: <_SelectorDatagramTransport fd=15 read=polling write=<idle, bufsize=0>>
2022-03-30 17:32:08 ERROR (MainThread) [custom_components.hacs] Request exception for 'https://api.github.com/rate_limit' with - Cannot connect to host api.github.com:443 ssl:default [Try again]
Traceback (most recent call last):
  File "/config/custom_components/hacs/base.py", line 427, in async_can_update
    response = await self.async_github_api_method(self.githubapi.rate_limit)
  File "/config/custom_components/hacs/base.py", line 478, in async_github_api_method
    raise HacsException(_exception)
custom_components.hacs.exceptions.HacsException: Request exception for 'https://api.github.com/rate_limit' with - Cannot connect to host api.github.com:443 ssl:default [Try again]
2022-03-30 17:33:46 ERROR (MainThread) [async_upnp_client.ssdp] Received error: [Errno 101] Network unreachable, transport: <_SelectorDatagramTransport fd=15 read=polling write=<idle, bufsize=0>>
2022-03-30 17:33:46 ERROR (MainThread) [async_upnp_client.ssdp] Received error: [Errno 101] Network unreachable, transport: <_SelectorDatagramTransport fd=15 read=polling write=<idle, bufsize=0>>
2022-03-30 17:35:46 ERROR (MainThread) [async_upnp_client.ssdp] Received error: [Errno 101] Network unreachable, transport: <_SelectorDatagramTransport fd=15 read=polling write=<idle, bufsize=0>>
2022-03-30 17:35:46 ERROR (MainThread) [async_upnp_client.ssdp] Received error: [Errno 101] Network unreachable, transport: <_SelectorDatagramTransport fd=15 read=polling write=<idle, bufsize=0>>
2022-03-30 17:37:46 ERROR (MainThread) [async_upnp_client.ssdp] Received error: [Errno 101] Network unreachable, transport: <_SelectorDatagramTransport fd=15 read=polling write=<idle, bufsize=0>>
2022-03-30 17:37:46 ERROR (MainThread) [async_upnp_client.ssdp] Received error: [Errno 101] Network unreachable, transport: <_SelectorDatagramTransport fd=15 read=polling write=<idle, bufsize=0>>
2022-03-30 17:39:46 ERROR (MainThread) [async_upnp_client.ssdp] Received error: [Errno 101] Network unreachable, transport: <_SelectorDatagramTransport fd=15 read=polling write=<idle, bufsize=0>>
2022-03-30 17:39:46 ERROR (MainThread) [async_upnp_client.ssdp] Received error: [Errno 101] Network unreachable, transport: <_SelectorDatagramTransport fd=15 read=polling write=<idle, bufsize=0>>
2022-03-30 17:41:46 ERROR (MainThread) [async_upnp_client.ssdp] Received error: [Errno 101] Network unreachable, transport: <_SelectorDatagramTransport fd=15 read=polling write=<idle, bufsize=0>>
2022-03-30 17:41:46 ERROR (MainThread) [async_upnp_client.ssdp] Received error: [Errno 101] Network unreachable, transport: <_SelectorDatagramTransport fd=15 read=polling write=<idle, bufsize=0>>
2022-03-30 17:42:08 ERROR (MainThread) [custom_components.hacs] Request exception for 'https://api.github.com/rate_limit' with - Cannot connect to host api.github.com:443 ssl:default [Try again]
Traceback (most recent call last):
  File "/config/custom_components/hacs/base.py", line 427, in async_can_update
    response = await self.async_github_api_method(self.githubapi.rate_limit)
  File "/config/custom_components/hacs/base.py", line 478, in async_github_api_method
    raise HacsException(_exception)
custom_components.hacs.exceptions.HacsException: Request exception for 'https://api.github.com/rate_limit' with - Cannot connect to host api.github.com:443 ssl:default [Try again]
2022-03-30 17:43:46 ERROR (MainThread) [async_upnp_client.ssdp] Received error: [Errno 101] Network unreachable, transport: <_SelectorDatagramTransport fd=15 read=polling write=<idle, bufsize=0>>
2022-03-30 17:43:46 ERROR (MainThread) [async_upnp_client.ssdp] Received error: [Errno 101] Network unreachable, transport: <_SelectorDatagramTransport fd=15 read=polling write=<idle, bufsize=0>>
2022-03-30 17:45:46 ERROR (MainThread) [async_upnp_client.ssdp] Received error: [Errno 101] Network unreachable, transport: <_SelectorDatagramTransport fd=15 read=polling write=<idle, bufsize=0>>
2022-03-30 17:45:47 ERROR (MainThread) [async_upnp_client.ssdp] Received error: [Errno 101] Network unreachable, transport: <_SelectorDatagramTransport fd=15 read=polling write=<idle, bufsize=0>>
2022-03-30 17:47:46 ERROR (MainThread) [async_upnp_client.ssdp] Received error: [Errno 101] Network unreachable, transport: <_SelectorDatagramTransport fd=15 read=polling write=<idle, bufsize=0>>
2022-03-30 17:47:47 ERROR (MainThread) [async_upnp_client.ssdp] Received error: [Errno 101] Network unreachable, transport: <_SelectorDatagramTransport fd=15 read=polling write=<idle, bufsize=0>>
2022-03-30 17:49:47 ERROR (MainThread) [async_upnp_client.ssdp] Received error: [Errno 101] Network unreachable, transport: <_SelectorDatagramTransport fd=15 read=polling write=<idle, bufsize=0>>
2022-03-30 17:49:47 ERROR (MainThread) [async_upnp_client.ssdp] Received error: [Errno 101] Network unreachable, transport: <_SelectorDatagramTransport fd=15 read=polling write=<idle, bufsize=0>>
2022-03-30 17:51:47 ERROR (MainThread) [async_upnp_client.ssdp] Received error: [Errno 101] Network unreachable, transport: <_SelectorDatagramTransport fd=15 read=polling write=<idle, bufsize=0>>
2022-03-30 17:51:47 ERROR (MainThread) [async_upnp_client.ssdp] Received error: [Errno 101] Network unreachable, transport: <_SelectorDatagramTransport fd=15 read=polling write=<idle, bufsize=0>>
2022-03-30 17:52:08 ERROR (MainThread) [custom_components.hacs] Request exception for 'https://api.github.com/rate_limit' with - Cannot connect to host api.github.com:443 ssl:default [Try again]
Traceback (most recent call last):
  File "/config/custom_components/hacs/base.py", line 427, in async_can_update
    response = await self.async_github_api_method(self.githubapi.rate_limit)
  File "/config/custom_components/hacs/base.py", line 478, in async_github_api_method
    raise HacsException(_exception)
custom_components.hacs.exceptions.HacsException: Request exception for 'https://api.github.com/rate_limit' with - Cannot connect to host api.github.com:443 ssl:default [Try again]
2022-03-30 17:53:47 ERROR (MainThread) [async_upnp_client.ssdp] Received error: [Errno 101] Network unreachable, transport: <_SelectorDatagramTransport fd=15 read=polling write=<idle, bufsize=0>>
2022-03-30 17:53:47 ERROR (MainThread) [async_upnp_client.ssdp] Received error: [Errno 101] Network unreachable, transport: <_SelectorDatagramTransport fd=15 read=polling write=<idle, bufsize=0>>
2022-03-30 17:55:47 ERROR (MainThread) [async_upnp_client.ssdp] Received error: [Errno 101] Network unreachable, transport: <_SelectorDatagramTransport fd=15 read=polling write=<idle, bufsize=0>>
2022-03-30 17:55:47 ERROR (MainThread) [async_upnp_client.ssdp] Received error: [Errno 101] Network unreachable, transport: <_SelectorDatagramTransport fd=15 read=polling write=<idle, bufsize=0>>
2022-03-30 17:57:47 ERROR (MainThread) [async_upnp_client.ssdp] Received error: [Errno 101] Network unreachable, transport: <_SelectorDatagramTransport fd=15 read=polling write=<idle, bufsize=0>>
2022-03-30 17:57:47 ERROR (MainThread) [async_upnp_client.ssdp] Received error: [Errno 101] Network unreachable, transport: <_SelectorDatagramTransport fd=15 read=polling write=<idle, bufsize=0>>
2022-03-30 17:59:47 ERROR (MainThread) [async_upnp_client.ssdp] Received error: [Errno 101] Network unreachable, transport: <_SelectorDatagramTransport fd=15 read=polling write=<idle, bufsize=0>>
2022-03-30 17:59:47 ERROR (MainThread) [async_upnp_client.ssdp] Received error: [Errno 101] Network unreachable, transport: <_SelectorDatagramTransport fd=15 read=polling write=<idle, bufsize=0>>
2022-03-30 18:01:47 ERROR (MainThread) [async_upnp_client.ssdp] Received error: [Errno 101] Network unreachable, transport: <_SelectorDatagramTransport fd=15 read=polling write=<idle, bufsize=0>>
2022-03-30 18:01:47 ERROR (MainThread) [async_upnp_client.ssdp] Received error: [Errno 101] Network unreachable, transport: <_SelectorDatagramTransport fd=15 read=polling write=<idle, bufsize=0>>
2022-03-30 18:02:08 ERROR (MainThread) [custom_components.hacs] Request exception for 'https://api.github.com/rate_limit' with - Cannot connect to host api.github.com:443 ssl:default [Try again]
Traceback (most recent call last):
  File "/config/custom_components/hacs/base.py", line 427, in async_can_update
    response = await self.async_github_api_method(self.githubapi.rate_limit)
  File "/config/custom_components/hacs/base.py", line 478, in async_github_api_method
    raise HacsException(_exception)
custom_components.hacs.exceptions.HacsException: Request exception for 'https://api.github.com/rate_limit' with - Cannot connect to host api.github.com:443 ssl:default [Try again]
2022-03-30 18:02:15 ERROR (MainThread) [homeassistant.components.forecast_solar] Unexpected error fetching forecast_solar data: Error while resolving Forecast.Solar API address
Traceback (most recent call last):
  File "/usr/local/lib/python3.9/site-packages/forecast_solar/__init__.py", line 72, in _request
    result = await dns.query("api.forecast.solar", "A")
aiodns.error.DNSError: (11, 'Could not contact DNS servers')

The above exception was the direct cause of the following exception:

Traceback (most recent call last):
  File "/usr/src/homeassistant/homeassistant/helpers/update_coordinator.py", line 187, in _async_refresh
    self.data = await self._async_update_data()
  File "/usr/src/homeassistant/homeassistant/helpers/update_coordinator.py", line 147, in _async_update_data
    return await self.update_method()
  File "/usr/local/lib/python3.9/site-packages/forecast_solar/__init__.py", line 138, in estimate
    data = await self._request(
  File "/usr/local/lib/python3.9/site-packages/forecast_solar/__init__.py", line 74, in _request
    raise ForecastSolarConnectionError(
forecast_solar.exceptions.ForecastSolarConnectionError: Error while resolving Forecast.Solar API address
2022-03-30 18:02:23 ERROR (MainThread) [homeassistant] Error doing job: Task exception was never retrieved
Traceback (most recent call last):
  File "/usr/src/homeassistant/homeassistant/components/dhcp/__init__.py", line 287, in async_discover
    for host in await self._discover_hosts.async_discover():
  File "/usr/local/lib/python3.9/site-packages/aiodiscover/discovery.py", line 143, in async_discover
    sys_network_data = await loop.run_in_executor(None, self._get_sys_network_data)
  File "/usr/local/lib/python3.9/concurrent/futures/thread.py", line 58, in run
    result = self.fn(*self.args, **self.kwargs)
  File "/usr/local/lib/python3.9/site-packages/aiodiscover/discovery.py", line 137, in _get_sys_network_data
    sys_network_data.setup()
  File "/usr/local/lib/python3.9/site-packages/aiodiscover/network.py", line 155, in setup
    self.network = get_network(self.local_ip, self.adapters)
  File "/usr/local/lib/python3.9/site-packages/aiodiscover/network.py", line 74, in get_network
    return ip_network(f"{local_ip}/{network_prefix}", False)
  File "/usr/local/lib/python3.9/ipaddress.py", line 83, in ip_network
    raise ValueError('%r does not appear to be an IPv4 or IPv6 network' %
ValueError: 'None/24' does not appear to be an IPv4 or IPv6 network
2022-03-30 18:02:33 ERROR (MainThread) [custom_components.hacs] <Integration AlexxIT/SonoffLAN> Cannot connect to host api.github.com:443 ssl:default [Try again]
2022-03-30 18:02:38 ERROR (MainThread) [custom_components.hacs] <Integration hacs/integration> Cannot connect to host api.github.com:443 ssl:default [Try again]
2022-03-30 18:03:47 ERROR (MainThread) [async_upnp_client.ssdp] Received error: [Errno 101] Network unreachable, transport: <_SelectorDatagramTransport fd=15 read=polling write=<idle, bufsize=0>>
2022-03-30 18:03:47 ERROR (MainThread) [async_upnp_client.ssdp] Received error: [Errno 101] Network unreachable, transport: <_SelectorDatagramTransport fd=15 read=polling write=<idle, bufsize=0>>
2022-03-30 18:05:47 ERROR (MainThread) [async_upnp_client.ssdp] Received error: [Errno 101] Network unreachable, transport: <_SelectorDatagramTransport fd=15 read=polling write=<idle, bufsize=0>>
2022-03-30 18:05:47 ERROR (MainThread) [async_upnp_client.ssdp] Received error: [Errno 101] Network unreachable, transport: <_SelectorDatagramTransport fd=15 read=polling write=<idle, bufsize=0>>
2022-03-30 18:07:47 ERROR (MainThread) [async_upnp_client.ssdp] Received error: [Errno 101] Network unreachable, transport: <_SelectorDatagramTransport fd=15 read=polling write=<idle, bufsize=0>>
2022-03-30 18:07:47 ERROR (MainThread) [async_upnp_client.ssdp] Received error: [Errno 101] Network unreachable, transport: <_SelectorDatagramTransport fd=15 read=polling write=<idle, bufsize=0>>
2022-03-30 18:09:47 ERROR (MainThread) [async_upnp_client.ssdp] Received error: [Errno 101] Network unreachable, transport: <_SelectorDatagramTransport fd=15 read=polling write=<idle, bufsize=0>>
2022-03-30 18:09:47 ERROR (MainThread) [async_upnp_client.ssdp] Received error: [Errno 101] Network unreachable, transport: <_SelectorDatagramTransport fd=15 read=polling write=<idle, bufsize=0>>
2022-03-30 18:11:47 ERROR (MainThread) [async_upnp_client.ssdp] Received error: [Errno 101] Network unreachable, transport: <_SelectorDatagramTransport fd=15 read=polling write=<idle, bufsize=0>>
2022-03-30 18:11:47 ERROR (MainThread) [async_upnp_client.ssdp] Received error: [Errno 101] Network unreachable, transport: <_SelectorDatagramTransport fd=15 read=polling write=<idle, bufsize=0>>
2022-03-30 18:12:08 ERROR (MainThread) [custom_components.hacs] Request exception for 'https://api.github.com/rate_limit' with - Cannot connect to host api.github.com:443 ssl:default [Try again]
Traceback (most recent call last):
  File "/config/custom_components/hacs/base.py", line 427, in async_can_update
    response = await self.async_github_api_method(self.githubapi.rate_limit)
  File "/config/custom_components/hacs/base.py", line 478, in async_github_api_method
    raise HacsException(_exception)
custom_components.hacs.exceptions.HacsException: Request exception for 'https://api.github.com/rate_limit' with - Cannot connect to host api.github.com:443 ssl:default [Try again]
2022-03-30 18:13:47 ERROR (MainThread) [async_upnp_client.ssdp] Received error: [Errno 101] Network unreachable, transport: <_SelectorDatagramTransport fd=15 read=polling write=<idle, bufsize=0>>
2022-03-30 18:13:47 ERROR (MainThread) [async_upnp_client.ssdp] Received error: [Errno 101] Network unreachable, transport: <_SelectorDatagramTransport fd=15 read=polling write=<idle, bufsize=0>>
2022-03-30 18:15:47 ERROR (MainThread) [async_upnp_client.ssdp] Received error: [Errno 101] Network unreachable, transport: <_SelectorDatagramTransport fd=15 read=polling write=<idle, bufsize=0>>
2022-03-30 18:15:47 ERROR (MainThread) [async_upnp_client.ssdp] Received error: [Errno 101] Network unreachable, transport: <_SelectorDatagramTransport fd=15 read=polling write=<idle, bufsize=0>>
2022-03-30 18:17:47 ERROR (MainThread) [async_upnp_client.ssdp] Received error: [Errno 101] Network unreachable, transport: <_SelectorDatagramTransport fd=15 read=polling write=<idle, bufsize=0>>
2022-03-30 18:17:47 ERROR (MainThread) [async_upnp_client.ssdp] Received error: [Errno 101] Network unreachable, transport: <_SelectorDatagramTransport fd=15 read=polling write=<idle, bufsize=0>>
2022-03-30 18:18:31 ERROR (MainThread) [metno] Access to https://aa015h6buqvih86i1.api.met.no/weatherapi/locationforecast/2.0/complete returned error 'ClientConnectorError'
2022-03-30 18:19:47 ERROR (MainThread) [async_upnp_client.ssdp] Received error: [Errno 101] Network unreachable, transport: <_SelectorDatagramTransport fd=15 read=polling write=<idle, bufsize=0>>
2022-03-30 18:19:47 ERROR (MainThread) [async_upnp_client.ssdp] Received error: [Errno 101] Network unreachable, transport: <_SelectorDatagramTransport fd=15 read=polling write=<idle, bufsize=0>>
2022-03-30 18:21:47 ERROR (MainThread) [async_upnp_client.ssdp] Received error: [Errno 101] Network unreachable, transport: <_SelectorDatagramTransport fd=15 read=polling write=<idle, bufsize=0>>
2022-03-30 18:21:47 ERROR (MainThread) [async_upnp_client.ssdp] Received error: [Errno 101] Network unreachable, transport: <_SelectorDatagramTransport fd=15 read=polling write=<idle, bufsize=0>>
2022-03-30 18:22:08 ERROR (MainThread) [custom_components.hacs] Request exception for 'https://api.github.com/rate_limit' with - Cannot connect to host api.github.com:443 ssl:default [Try again]
Traceback (most recent call last):
  File "/config/custom_components/hacs/base.py", line 427, in async_can_update
    response = await self.async_github_api_method(self.githubapi.rate_limit)
  File "/config/custom_components/hacs/base.py", line 478, in async_github_api_method
    raise HacsException(_exception)
custom_components.hacs.exceptions.HacsException: Request exception for 'https://api.github.com/rate_limit' with - Cannot connect to host api.github.com:443 ssl:default [Try again]
2022-03-30 18:23:47 ERROR (MainThread) [async_upnp_client.ssdp] Received error: [Errno 101] Network unreachable, transport: <_SelectorDatagramTransport fd=15 read=polling write=<idle, bufsize=0>>
2022-03-30 18:23:47 ERROR (MainThread) [async_upnp_client.ssdp] Received error: [Errno 101] Network unreachable, transport: <_SelectorDatagramTransport fd=15 read=polling write=<idle, bufsize=0>>
2022-03-30 18:25:47 ERROR (MainThread) [async_upnp_client.ssdp] Received error: [Errno 101] Network unreachable, transport: <_SelectorDatagramTransport fd=15 read=polling write=<idle, bufsize=0>>
2022-03-30 18:25:47 ERROR (MainThread) [async_upnp_client.ssdp] Received error: [Errno 101] Network unreachable, transport: <_SelectorDatagramTransport fd=15 read=polling write=<idle, bufsize=0>>
2022-03-30 18:27:47 ERROR (MainThread) [async_upnp_client.ssdp] Received error: [Errno 101] Network unreachable, transport: <_SelectorDatagramTransport fd=15 read=polling write=<idle, bufsize=0>>
2022-03-30 18:27:47 ERROR (MainThread) [async_upnp_client.ssdp] Received error: [Errno 101] Network unreachable, transport: <_SelectorDatagramTransport fd=15 read=polling write=<idle, bufsize=0>>
2022-03-30 18:29:47 ERROR (MainThread) [async_upnp_client.ssdp] Received error: [Errno 101] Network unreachable, transport: <_SelectorDatagramTransport fd=15 read=polling write=<idle, bufsize=0>>
2022-03-30 18:29:47 ERROR (MainThread) [async_upnp_client.ssdp] Received error: [Errno 101] Network unreachable, transport: <_SelectorDatagramTransport fd=15 read=polling write=<idle, bufsize=0>>
2022-03-30 18:31:47 ERROR (MainThread) [async_upnp_client.ssdp] Received error: [Errno 101] Network unreachable, transport: <_SelectorDatagramTransport fd=15 read=polling write=<idle, bufsize=0>>
2022-03-30 18:31:47 ERROR (MainThread) [async_upnp_client.ssdp] Received error: [Errno 101] Network unreachable, transport: <_SelectorDatagramTransport fd=15 read=polling write=<idle, bufsize=0>>
2022-03-30 18:32:08 ERROR (MainThread) [custom_components.hacs] Request exception for 'https://api.github.com/rate_limit' with - Cannot connect to host api.github.com:443 ssl:default [Try again]
Traceback (most recent call last):
  File "/config/custom_components/hacs/base.py", line 427, in async_can_update
    response = await self.async_github_api_method(self.githubapi.rate_limit)
  File "/config/custom_components/hacs/base.py", line 478, in async_github_api_method
    raise HacsException(_exception)
custom_components.hacs.exceptions.HacsException: Request exception for 'https://api.github.com/rate_limit' with - Cannot connect to host api.github.com:443 ssl:default [Try again]
2022-03-30 18:33:47 ERROR (MainThread) [async_upnp_client.ssdp] Received error: [Errno 101] Network unreachable, transport: <_SelectorDatagramTransport fd=15 read=polling write=<idle, bufsize=0>>
2022-03-30 18:33:47 ERROR (MainThread) [async_upnp_client.ssdp] Received error: [Errno 101] Network unreachable, transport: <_SelectorDatagramTransport fd=15 read=polling write=<idle, bufsize=0>>
2022-03-30 18:35:47 ERROR (MainThread) [async_upnp_client.ssdp] Received error: [Errno 101] Network unreachable, transport: <_SelectorDatagramTransport fd=15 read=polling write=<idle, bufsize=0>>
2022-03-30 18:35:47 ERROR (MainThread) [async_upnp_client.ssdp] Received error: [Errno 101] Network unreachable, transport: <_SelectorDatagramTransport fd=15 read=polling write=<idle, bufsize=0>>
2022-03-30 18:37:47 ERROR (MainThread) [async_upnp_client.ssdp] Received error: [Errno 101] Network unreachable, transport: <_SelectorDatagramTransport fd=15 read=polling write=<idle, bufsize=0>>
2022-03-30 18:37:47 ERROR (MainThread) [async_upnp_client.ssdp] Received error: [Errno 101] Network unreachable, transport: <_SelectorDatagramTransport fd=15 read=polling write=<idle, bufsize=0>>
2022-03-30 18:39:47 ERROR (MainThread) [async_upnp_client.ssdp] Received error: [Errno 101] Network unreachable, transport: <_SelectorDatagramTransport fd=15 read=polling write=<idle, bufsize=0>>
2022-03-30 18:39:47 ERROR (MainThread) [async_upnp_client.ssdp] Received error: [Errno 101] Network unreachable, transport: <_SelectorDatagramTransport fd=15 read=polling write=<idle, bufsize=0>>
2022-03-30 18:41:47 ERROR (MainThread) [async_upnp_client.ssdp] Received error: [Errno 101] Network unreachable, transport: <_SelectorDatagramTransport fd=15 read=polling write=<idle, bufsize=0>>
2022-03-30 18:41:47 ERROR (MainThread) [async_upnp_client.ssdp] Received error: [Errno 101] Network unreachable, transport: <_SelectorDatagramTransport fd=15 read=polling write=<idle, bufsize=0>>
2022-03-30 18:42:08 ERROR (MainThread) [custom_components.hacs] Request exception for 'https://api.github.com/rate_limit' with - Cannot connect to host api.github.com:443 ssl:default [Try again]
Traceback (most recent call last):
  File "/config/custom_components/hacs/base.py", line 427, in async_can_update
    response = await self.async_github_api_method(self.githubapi.rate_limit)
  File "/config/custom_components/hacs/base.py", line 478, in async_github_api_method
    raise HacsException(_exception)
custom_components.hacs.exceptions.HacsException: Request exception for 'https://api.github.com/rate_limit' with - Cannot connect to host api.github.com:443 ssl:default [Try again]
2022-03-30 18:43:47 ERROR (MainThread) [async_upnp_client.ssdp] Received error: [Errno 101] Network unreachable, transport: <_SelectorDatagramTransport fd=15 read=polling write=<idle, bufsize=0>>
2022-03-30 18:43:47 ERROR (MainThread) [async_upnp_client.ssdp] Received error: [Errno 101] Network unreachable, transport: <_SelectorDatagramTransport fd=15 read=polling write=<idle, bufsize=0>>
2022-03-30 18:45:47 ERROR (MainThread) [async_upnp_client.ssdp] Received error: [Errno 101] Network unreachable, transport: <_SelectorDatagramTransport fd=15 read=polling write=<idle, bufsize=0>>
2022-03-30 18:45:47 ERROR (MainThread) [async_upnp_client.ssdp] Received error: [Errno 101] Network unreachable, transport: <_SelectorDatagramTransport fd=15 read=polling write=<idle, bufsize=0>>
2022-03-30 18:47:47 ERROR (MainThread) [async_upnp_client.ssdp] Received error: [Errno 101] Network unreachable, transport: <_SelectorDatagramTransport fd=15 read=polling write=<idle, bufsize=0>>
2022-03-30 18:47:47 ERROR (MainThread) [async_upnp_client.ssdp] Received error: [Errno 101] Network unreachable, transport: <_SelectorDatagramTransport fd=15 read=polling write=<idle, bufsize=0>>
2022-03-30 18:49:47 ERROR (MainThread) [async_upnp_client.ssdp] Received error: [Errno 101] Network unreachable, transport: <_SelectorDatagramTransport fd=15 read=polling write=<idle, bufsize=0>>
2022-03-30 18:49:47 ERROR (MainThread) [async_upnp_client.ssdp] Received error: [Errno 101] Network unreachable, transport: <_SelectorDatagramTransport fd=15 read=polling write=<idle, bufsize=0>>
2022-03-30 18:51:47 ERROR (MainThread) [async_upnp_client.ssdp] Received error: [Errno 101] Network unreachable, transport: <_SelectorDatagramTransport fd=15 read=polling write=<idle, bufsize=0>>
2022-03-30 18:51:47 ERROR (MainThread) [async_upnp_client.ssdp] Received error: [Errno 101] Network unreachable, transport: <_SelectorDatagramTransport fd=15 read=polling write=<idle, bufsize=0>>
2022-03-30 18:52:08 ERROR (MainThread) [custom_components.hacs] Request exception for 'https://api.github.com/rate_limit' with - Cannot connect to host api.github.com:443 ssl:default [Try again]
Traceback (most recent call last):
  File "/config/custom_components/hacs/base.py", line 427, in async_can_update
    response = await self.async_github_api_method(self.githubapi.rate_limit)
  File "/config/custom_components/hacs/base.py", line 478, in async_github_api_method
    raise HacsException(_exception)
custom_components.hacs.exceptions.HacsException: Request exception for 'https://api.github.com/rate_limit' with - Cannot connect to host api.github.com:443 ssl:default [Try again]
2022-03-30 18:53:47 ERROR (MainThread) [async_upnp_client.ssdp] Received error: [Errno 101] Network unreachable, transport: <_SelectorDatagramTransport fd=15 read=polling write=<idle, bufsize=0>>
2022-03-30 18:53:47 ERROR (MainThread) [async_upnp_client.ssdp] Received error: [Errno 101] Network unreachable, transport: <_SelectorDatagramTransport fd=15 read=polling write=<idle, bufsize=0>>
2022-03-30 18:55:47 ERROR (MainThread) [async_upnp_client.ssdp] Received error: [Errno 101] Network unreachable, transport: <_SelectorDatagramTransport fd=15 read=polling write=<idle, bufsize=0>>
2022-03-30 18:55:47 ERROR (MainThread) [async_upnp_client.ssdp] Received error: [Errno 101] Network unreachable, transport: <_SelectorDatagramTransport fd=15 read=polling write=<idle, bufsize=0>>
2022-03-30 18:57:47 ERROR (MainThread) [async_upnp_client.ssdp] Received error: [Errno 101] Network unreachable, transport: <_SelectorDatagramTransport fd=15 read=polling write=<idle, bufsize=0>>
2022-03-30 18:57:47 ERROR (MainThread) [async_upnp_client.ssdp] Received error: [Errno 101] Network unreachable, transport: <_SelectorDatagramTransport fd=15 read=polling write=<idle, bufsize=0>>
2022-03-30 18:59:47 ERROR (MainThread) [async_upnp_client.ssdp] Received error: [Errno 101] Network unreachable, transport: <_SelectorDatagramTransport fd=15 read=polling write=<idle, bufsize=0>>
2022-03-30 18:59:47 ERROR (MainThread) [async_upnp_client.ssdp] Received error: [Errno 101] Network unreachable, transport: <_SelectorDatagramTransport fd=15 read=polling write=<idle, bufsize=0>>
2022-03-30 19:01:47 ERROR (MainThread) [async_upnp_client.ssdp] Received error: [Errno 101] Network unreachable, transport: <_SelectorDatagramTransport fd=15 read=polling write=<idle, bufsize=0>>
2022-03-30 19:01:47 ERROR (MainThread) [async_upnp_client.ssdp] Received error: [Errno 101] Network unreachable, transport: <_SelectorDatagramTransport fd=15 read=polling write=<idle, bufsize=0>>
2022-03-30 19:02:08 ERROR (MainThread) [custom_components.hacs] Request exception for 'https://api.github.com/rate_limit' with - Cannot connect to host api.github.com:443 ssl:default [Try again]
Traceback (most recent call last):
  File "/config/custom_components/hacs/base.py", line 427, in async_can_update
    response = await self.async_github_api_method(self.githubapi.rate_limit)
  File "/config/custom_components/hacs/base.py", line 478, in async_github_api_method
    raise HacsException(_exception)
custom_components.hacs.exceptions.HacsException: Request exception for 'https://api.github.com/rate_limit' with - Cannot connect to host api.github.com:443 ssl:default [Try again]
2022-03-30 19:02:15 ERROR (MainThread) [homeassistant.components.forecast_solar] Unexpected error fetching forecast_solar data: Error while resolving Forecast.Solar API address
Traceback (most recent call last):
  File "/usr/local/lib/python3.9/site-packages/forecast_solar/__init__.py", line 72, in _request
    result = await dns.query("api.forecast.solar", "A")
aiodns.error.DNSError: (11, 'Could not contact DNS servers')

The above exception was the direct cause of the following exception:

Traceback (most recent call last):
  File "/usr/src/homeassistant/homeassistant/helpers/update_coordinator.py", line 187, in _async_refresh
    self.data = await self._async_update_data()
  File "/usr/src/homeassistant/homeassistant/helpers/update_coordinator.py", line 147, in _async_update_data
    return await self.update_method()
  File "/usr/local/lib/python3.9/site-packages/forecast_solar/__init__.py", line 138, in estimate
    data = await self._request(
  File "/usr/local/lib/python3.9/site-packages/forecast_solar/__init__.py", line 74, in _request
    raise ForecastSolarConnectionError(
forecast_solar.exceptions.ForecastSolarConnectionError: Error while resolving Forecast.Solar API address
2022-03-30 19:02:23 ERROR (MainThread) [homeassistant] Error doing job: Task exception was never retrieved
Traceback (most recent call last):
  File "/usr/src/homeassistant/homeassistant/components/dhcp/__init__.py", line 287, in async_discover
    for host in await self._discover_hosts.async_discover():
  File "/usr/local/lib/python3.9/site-packages/aiodiscover/discovery.py", line 143, in async_discover
    sys_network_data = await loop.run_in_executor(None, self._get_sys_network_data)
  File "/usr/local/lib/python3.9/concurrent/futures/thread.py", line 58, in run
    result = self.fn(*self.args, **self.kwargs)
  File "/usr/local/lib/python3.9/site-packages/aiodiscover/discovery.py", line 137, in _get_sys_network_data
    sys_network_data.setup()
  File "/usr/local/lib/python3.9/site-packages/aiodiscover/network.py", line 155, in setup
    self.network = get_network(self.local_ip, self.adapters)
  File "/usr/local/lib/python3.9/site-packages/aiodiscover/network.py", line 74, in get_network
    return ip_network(f"{local_ip}/{network_prefix}", False)
  File "/usr/local/lib/python3.9/ipaddress.py", line 83, in ip_network
    raise ValueError('%r does not appear to be an IPv4 or IPv6 network' %
ValueError: 'None/24' does not appear to be an IPv4 or IPv6 network
2022-03-30 19:03:47 ERROR (MainThread) [async_upnp_client.ssdp] Received error: [Errno 101] Network unreachable, transport: <_SelectorDatagramTransport fd=15 read=polling write=<idle, bufsize=0>>
2022-03-30 19:03:47 ERROR (MainThread) [async_upnp_client.ssdp] Received error: [Errno 101] Network unreachable, transport: <_SelectorDatagramTransport fd=15 read=polling write=<idle, bufsize=0>>
2022-03-30 19:05:47 ERROR (MainThread) [async_upnp_client.ssdp] Received error: [Errno 101] Network unreachable, transport: <_SelectorDatagramTransport fd=15 read=polling write=<idle, bufsize=0>>
2022-03-30 19:05:47 ERROR (MainThread) [async_upnp_client.ssdp] Received error: [Errno 101] Network unreachable, transport: <_SelectorDatagramTransport fd=15 read=polling write=<idle, bufsize=0>>
2022-03-30 19:07:47 ERROR (MainThread) [async_upnp_client.ssdp] Received error: [Errno 101] Network unreachable, transport: <_SelectorDatagramTransport fd=15 read=polling write=<idle, bufsize=0>>
2022-03-30 19:07:47 ERROR (MainThread) [async_upnp_client.ssdp] Received error: [Errno 101] Network unreachable, transport: <_SelectorDatagramTransport fd=15 read=polling write=<idle, bufsize=0>>
2022-03-30 19:09:47 ERROR (MainThread) [async_upnp_client.ssdp] Received error: [Errno 101] Network unreachable, transport: <_SelectorDatagramTransport fd=15 read=polling write=<idle, bufsize=0>>
2022-03-30 19:09:47 ERROR (MainThread) [async_upnp_client.ssdp] Received error: [Errno 101] Network unreachable, transport: <_SelectorDatagramTransport fd=15 read=polling write=<idle, bufsize=0>>
2022-03-30 19:11:47 ERROR (MainThread) [async_upnp_client.ssdp] Received error: [Errno 101] Network unreachable, transport: <_SelectorDatagramTransport fd=15 read=polling write=<idle, bufsize=0>>
2022-03-30 19:11:47 ERROR (MainThread) [async_upnp_client.ssdp] Received error: [Errno 101] Network unreachable, transport: <_SelectorDatagramTransport fd=15 read=polling write=<idle, bufsize=0>>
2022-03-30 19:12:08 ERROR (MainThread) [custom_components.hacs] Request exception for 'https://api.github.com/rate_limit' with - Cannot connect to host api.github.com:443 ssl:default [Try again]
Traceback (most recent call last):
  File "/config/custom_components/hacs/base.py", line 427, in async_can_update
    response = await self.async_github_api_method(self.githubapi.rate_limit)
  File "/config/custom_components/hacs/base.py", line 478, in async_github_api_method
    raise HacsException(_exception)
custom_components.hacs.exceptions.HacsException: Request exception for 'https://api.github.com/rate_limit' with - Cannot connect to host api.github.com:443 ssl:default [Try again]
2022-03-30 19:13:47 ERROR (MainThread) [async_upnp_client.ssdp] Received error: [Errno 101] Network unreachable, transport: <_SelectorDatagramTransport fd=15 read=polling write=<idle, bufsize=0>>
2022-03-30 19:13:47 ERROR (MainThread) [async_upnp_client.ssdp] Received error: [Errno 101] Network unreachable, transport: <_SelectorDatagramTransport fd=15 read=polling write=<idle, bufsize=0>>
2022-03-30 19:14:36 ERROR (MainThread) [metno] Access to https://aa015h6buqvih86i1.api.met.no/weatherapi/locationforecast/2.0/complete returned error 'ClientConnectorError'
2022-03-30 19:15:47 ERROR (MainThread) [async_upnp_client.ssdp] Received error: [Errno 101] Network unreachable, transport: <_SelectorDatagramTransport fd=15 read=polling write=<idle, bufsize=0>>
2022-03-30 19:15:47 ERROR (MainThread) [async_upnp_client.ssdp] Received error: [Errno 101] Network unreachable, transport: <_SelectorDatagramTransport fd=15 read=polling write=<idle, bufsize=0>>
2022-03-30 19:17:47 ERROR (MainThread) [async_upnp_client.ssdp] Received error: [Errno 101] Network unreachable, transport: <_SelectorDatagramTransport fd=15 read=polling write=<idle, bufsize=0>>
2022-03-30 19:17:47 ERROR (MainThread) [async_upnp_client.ssdp] Received error: [Errno 101] Network unreachable, transport: <_SelectorDatagramTransport fd=15 read=polling write=<idle, bufsize=0>>
2022-03-30 19:19:47 ERROR (MainThread) [async_upnp_client.ssdp] Received error: [Errno 101] Network unreachable, transport: <_SelectorDatagramTransport fd=15 read=polling write=<idle, bufsize=0>>
2022-03-30 19:19:47 ERROR (MainThread) [async_upnp_client.ssdp] Received error: [Errno 101] Network unreachable, transport: <_SelectorDatagramTransport fd=15 read=polling write=<idle, bufsize=0>>
2022-03-30 19:21:47 ERROR (MainThread) [async_upnp_client.ssdp] Received error: [Errno 101] Network unreachable, transport: <_SelectorDatagramTransport fd=15 read=polling write=<idle, bufsize=0>>
2022-03-30 19:21:47 ERROR (MainThread) [async_upnp_client.ssdp] Received error: [Errno 101] Network unreachable, transport: <_SelectorDatagramTransport fd=15 read=polling write=<idle, bufsize=0>>
2022-03-30 19:22:08 ERROR (MainThread) [custom_components.hacs] Request exception for 'https://api.github.com/rate_limit' with - Cannot connect to host api.github.com:443 ssl:default [Try again]
Traceback (most recent call last):
  File "/config/custom_components/hacs/base.py", line 427, in async_can_update
    response = await self.async_github_api_method(self.githubapi.rate_limit)
  File "/config/custom_components/hacs/base.py", line 478, in async_github_api_method
    raise HacsException(_exception)
custom_components.hacs.exceptions.HacsException: Request exception for 'https://api.github.com/rate_limit' with - Cannot connect to host api.github.com:443 ssl:default [Try again]
2022-03-30 19:23:47 ERROR (MainThread) [async_upnp_client.ssdp] Received error: [Errno 101] Network unreachable, transport: <_SelectorDatagramTransport fd=15 read=polling write=<idle, bufsize=0>>
2022-03-30 19:23:47 ERROR (MainThread) [async_upnp_client.ssdp] Received error: [Errno 101] Network unreachable, transport: <_SelectorDatagramTransport fd=15 read=polling write=<idle, bufsize=0>>
2022-03-30 19:25:47 ERROR (MainThread) [async_upnp_client.ssdp] Received error: [Errno 101] Network unreachable, transport: <_SelectorDatagramTransport fd=15 read=polling write=<idle, bufsize=0>>
2022-03-30 19:25:47 ERROR (MainThread) [async_upnp_client.ssdp] Received error: [Errno 101] Network unreachable, transport: <_SelectorDatagramTransport fd=15 read=polling write=<idle, bufsize=0>>
2022-03-30 19:27:47 ERROR (MainThread) [async_upnp_client.ssdp] Received error: [Errno 101] Network unreachable, transport: <_SelectorDatagramTransport fd=15 read=polling write=<idle, bufsize=0>>
2022-03-30 19:27:47 ERROR (MainThread) [async_upnp_client.ssdp] Received error: [Errno 101] Network unreachable, transport: <_SelectorDatagramTransport fd=15 read=polling write=<idle, bufsize=0>>
2022-03-30 19:29:47 ERROR (MainThread) [async_upnp_client.ssdp] Received error: [Errno 101] Network unreachable, transport: <_SelectorDatagramTransport fd=15 read=polling write=<idle, bufsize=0>>
2022-03-30 19:29:47 ERROR (MainThread) [async_upnp_client.ssdp] Received error: [Errno 101] Network unreachable, transport: <_SelectorDatagramTransport fd=15 read=polling write=<idle, bufsize=0>>
2022-03-30 19:31:47 ERROR (MainThread) [async_upnp_client.ssdp] Received error: [Errno 101] Network unreachable, transport: <_SelectorDatagramTransport fd=15 read=polling write=<idle, bufsize=0>>
2022-03-30 19:31:47 ERROR (MainThread) [async_upnp_client.ssdp] Received error: [Errno 101] Network unreachable, transport: <_SelectorDatagramTransport fd=15 read=polling write=<idle, bufsize=0>>
2022-03-30 19:32:08 ERROR (MainThread) [custom_components.hacs] Request exception for 'https://api.github.com/rate_limit' with - Cannot connect to host api.github.com:443 ssl:default [Try again]
Traceback (most recent call last):
  File "/config/custom_components/hacs/base.py", line 427, in async_can_update
    response = await self.async_github_api_method(self.githubapi.rate_limit)
  File "/config/custom_components/hacs/base.py", line 478, in async_github_api_method
    raise HacsException(_exception)
custom_components.hacs.exceptions.HacsException: Request exception for 'https://api.github.com/rate_limit' with - Cannot connect to host api.github.com:443 ssl:default [Try again]
2022-03-30 19:33:47 ERROR (MainThread) [async_upnp_client.ssdp] Received error: [Errno 101] Network unreachable, transport: <_SelectorDatagramTransport fd=15 read=polling write=<idle, bufsize=0>>
2022-03-30 19:33:47 ERROR (MainThread) [async_upnp_client.ssdp] Received error: [Errno 101] Network unreachable, transport: <_SelectorDatagramTransport fd=15 read=polling write=<idle, bufsize=0>>
2022-03-30 19:35:47 ERROR (MainThread) [async_upnp_client.ssdp] Received error: [Errno 101] Network unreachable, transport: <_SelectorDatagramTransport fd=15 read=polling write=<idle, bufsize=0>>
2022-03-30 19:35:47 ERROR (MainThread) [async_upnp_client.ssdp] Received error: [Errno 101] Network unreachable, transport: <_SelectorDatagramTransport fd=15 read=polling write=<idle, bufsize=0>>
2022-03-30 19:37:47 ERROR (MainThread) [async_upnp_client.ssdp] Received error: [Errno 101] Network unreachable, transport: <_SelectorDatagramTransport fd=15 read=polling write=<idle, bufsize=0>>
2022-03-30 19:37:47 ERROR (MainThread) [async_upnp_client.ssdp] Received error: [Errno 101] Network unreachable, transport: <_SelectorDatagramTransport fd=15 read=polling write=<idle, bufsize=0>>
2022-03-30 19:39:47 ERROR (MainThread) [async_upnp_client.ssdp] Received error: [Errno 101] Network unreachable, transport: <_SelectorDatagramTransport fd=15 read=polling write=<idle, bufsize=0>>
2022-03-30 19:39:47 ERROR (MainThread) [async_upnp_client.ssdp] Received error: [Errno 101] Network unreachable, transport: <_SelectorDatagramTransport fd=15 read=polling write=<idle, bufsize=0>>
2022-03-30 19:41:47 ERROR (MainThread) [async_upnp_client.ssdp] Received error: [Errno 101] Network unreachable, transport: <_SelectorDatagramTransport fd=15 read=polling write=<idle, bufsize=0>>
2022-03-30 19:41:47 ERROR (MainThread) [async_upnp_client.ssdp] Received error: [Errno 101] Network unreachable, transport: <_SelectorDatagramTransport fd=15 read=polling write=<idle, bufsize=0>>
2022-03-30 19:42:08 ERROR (MainThread) [custom_components.hacs] Request exception for 'https://api.github.com/rate_limit' with - Cannot connect to host api.github.com:443 ssl:default [Try again]
Traceback (most recent call last):
  File "/config/custom_components/hacs/base.py", line 427, in async_can_update
    response = await self.async_github_api_method(self.githubapi.rate_limit)
  File "/config/custom_components/hacs/base.py", line 478, in async_github_api_method
    raise HacsException(_exception)
custom_components.hacs.exceptions.HacsException: Request exception for 'https://api.github.com/rate_limit' with - Cannot connect to host api.github.com:443 ssl:default [Try again]
2022-03-30 19:43:47 ERROR (MainThread) [async_upnp_client.ssdp] Received error: [Errno 101] Network unreachable, transport: <_SelectorDatagramTransport fd=15 read=polling write=<idle, bufsize=0>>
2022-03-30 19:43:47 ERROR (MainThread) [async_upnp_client.ssdp] Received error: [Errno 101] Network unreachable, transport: <_SelectorDatagramTransport fd=15 read=polling write=<idle, bufsize=0>>
2022-03-30 19:45:47 ERROR (MainThread) [async_upnp_client.ssdp] Received error: [Errno 101] Network unreachable, transport: <_SelectorDatagramTransport fd=15 read=polling write=<idle, bufsize=0>>
2022-03-30 19:45:47 ERROR (MainThread) [async_upnp_client.ssdp] Received error: [Errno 101] Network unreachable, transport: <_SelectorDatagramTransport fd=15 read=polling write=<idle, bufsize=0>>
2022-03-30 19:47:47 ERROR (MainThread) [async_upnp_client.ssdp] Received error: [Errno 101] Network unreachable, transport: <_SelectorDatagramTransport fd=15 read=polling write=<idle, bufsize=0>>
2022-03-30 19:47:47 ERROR (MainThread) [async_upnp_client.ssdp] Received error: [Errno 101] Network unreachable, transport: <_SelectorDatagramTransport fd=15 read=polling write=<idle, bufsize=0>>
2022-03-30 19:49:47 ERROR (MainThread) [async_upnp_client.ssdp] Received error: [Errno 101] Network unreachable, transport: <_SelectorDatagramTransport fd=15 read=polling write=<idle, bufsize=0>>
2022-03-30 19:49:47 ERROR (MainThread) [async_upnp_client.ssdp] Received error: [Errno 101] Network unreachable, transport: <_SelectorDatagramTransport fd=15 read=polling write=<idle, bufsize=0>>
2022-03-30 19:51:47 ERROR (MainThread) [async_upnp_client.ssdp] Received error: [Errno 101] Network unreachable, transport: <_SelectorDatagramTransport fd=15 read=polling write=<idle, bufsize=0>>
2022-03-30 19:51:47 ERROR (MainThread) [async_upnp_client.ssdp] Received error: [Errno 101] Network unreachable, transport: <_SelectorDatagramTransport fd=15 read=polling write=<idle, bufsize=0>>
2022-03-30 19:52:08 ERROR (MainThread) [custom_components.hacs] Request exception for 'https://api.github.com/rate_limit' with - Cannot connect to host api.github.com:443 ssl:default [Try again]
Traceback (most recent call last):
  File "/config/custom_components/hacs/base.py", line 427, in async_can_update
    response = await self.async_github_api_method(self.githubapi.rate_limit)
  File "/config/custom_components/hacs/base.py", line 478, in async_github_api_method
    raise HacsException(_exception)
custom_components.hacs.exceptions.HacsException: Request exception for 'https://api.github.com/rate_limit' with - Cannot connect to host api.github.com:443 ssl:default [Try again]
2022-03-30 19:53:47 ERROR (MainThread) [async_upnp_client.ssdp] Received error: [Errno 101] Network unreachable, transport: <_SelectorDatagramTransport fd=15 read=polling write=<idle, bufsize=0>>
2022-03-30 19:53:47 ERROR (MainThread) [async_upnp_client.ssdp] Received error: [Errno 101] Network unreachable, transport: <_SelectorDatagramTransport fd=15 read=polling write=<idle, bufsize=0>>
2022-03-30 19:55:47 ERROR (MainThread) [async_upnp_client.ssdp] Received error: [Errno 101] Network unreachable, transport: <_SelectorDatagramTransport fd=15 read=polling write=<idle, bufsize=0>>
2022-03-30 19:55:47 ERROR (MainThread) [async_upnp_client.ssdp] Received error: [Errno 101] Network unreachable, transport: <_SelectorDatagramTransport fd=15 read=polling write=<idle, bufsize=0>>
2022-03-30 19:57:47 ERROR (MainThread) [async_upnp_client.ssdp] Received error: [Errno 101] Network unreachable, transport: <_SelectorDatagramTransport fd=15 read=polling write=<idle, bufsize=0>>
2022-03-30 19:57:47 ERROR (MainThread) [async_upnp_client.ssdp] Received error: [Errno 101] Network unreachable, transport: <_SelectorDatagramTransport fd=15 read=polling write=<idle, bufsize=0>>
2022-03-30 19:59:47 ERROR (MainThread) [async_upnp_client.ssdp] Received error: [Errno 101] Network unreachable, transport: <_SelectorDatagramTransport fd=15 read=polling write=<idle, bufsize=0>>
2022-03-30 19:59:47 ERROR (MainThread) [async_upnp_client.ssdp] Received error: [Errno 101] Network unreachable, transport: <_SelectorDatagramTransport fd=15 read=polling write=<idle, bufsize=0>>
2022-03-30 20:01:47 ERROR (MainThread) [async_upnp_client.ssdp] Received error: [Errno 101] Network unreachable, transport: <_SelectorDatagramTransport fd=15 read=polling write=<idle, bufsize=0>>
2022-03-30 20:01:47 ERROR (MainThread) [async_upnp_client.ssdp] Received error: [Errno 101] Network unreachable, transport: <_SelectorDatagramTransport fd=15 read=polling write=<idle, bufsize=0>>
2022-03-30 20:02:08 ERROR (MainThread) [custom_components.hacs] Request exception for 'https://api.github.com/rate_limit' with - Cannot connect to host api.github.com:443 ssl:default [Try again]
Traceback (most recent call last):
  File "/config/custom_components/hacs/base.py", line 427, in async_can_update
    response = await self.async_github_api_method(self.githubapi.rate_limit)
  File "/config/custom_components/hacs/base.py", line 478, in async_github_api_method
    raise HacsException(_exception)
custom_components.hacs.exceptions.HacsException: Request exception for 'https://api.github.com/rate_limit' with - Cannot connect to host api.github.com:443 ssl:default [Try again]
2022-03-30 20:02:16 ERROR (MainThread) [homeassistant.components.forecast_solar] Unexpected error fetching forecast_solar data: Error while resolving Forecast.Solar API address
Traceback (most recent call last):
  File "/usr/local/lib/python3.9/site-packages/forecast_solar/__init__.py", line 72, in _request
    result = await dns.query("api.forecast.solar", "A")
aiodns.error.DNSError: (11, 'Could not contact DNS servers')

The above exception was the direct cause of the following exception:

Traceback (most recent call last):
  File "/usr/src/homeassistant/homeassistant/helpers/update_coordinator.py", line 187, in _async_refresh
    self.data = await self._async_update_data()
  File "/usr/src/homeassistant/homeassistant/helpers/update_coordinator.py", line 147, in _async_update_data
    return await self.update_method()
  File "/usr/local/lib/python3.9/site-packages/forecast_solar/__init__.py", line 138, in estimate
    data = await self._request(
  File "/usr/local/lib/python3.9/site-packages/forecast_solar/__init__.py", line 74, in _request
    raise ForecastSolarConnectionError(
forecast_solar.exceptions.ForecastSolarConnectionError: Error while resolving Forecast.Solar API address
2022-03-30 20:02:23 ERROR (MainThread) [homeassistant] Error doing job: Task exception was never retrieved
Traceback (most recent call last):
  File "/usr/src/homeassistant/homeassistant/components/dhcp/__init__.py", line 287, in async_discover
    for host in await self._discover_hosts.async_discover():
  File "/usr/local/lib/python3.9/site-packages/aiodiscover/discovery.py", line 143, in async_discover
    sys_network_data = await loop.run_in_executor(None, self._get_sys_network_data)
  File "/usr/local/lib/python3.9/concurrent/futures/thread.py", line 58, in run
    result = self.fn(*self.args, **self.kwargs)
  File "/usr/local/lib/python3.9/site-packages/aiodiscover/discovery.py", line 137, in _get_sys_network_data
    sys_network_data.setup()
  File "/usr/local/lib/python3.9/site-packages/aiodiscover/network.py", line 155, in setup
    self.network = get_network(self.local_ip, self.adapters)
  File "/usr/local/lib/python3.9/site-packages/aiodiscover/network.py", line 74, in get_network
    return ip_network(f"{local_ip}/{network_prefix}", False)
  File "/usr/local/lib/python3.9/ipaddress.py", line 83, in ip_network
    raise ValueError('%r does not appear to be an IPv4 or IPv6 network' %
ValueError: 'None/24' does not appear to be an IPv4 or IPv6 network
2022-03-30 20:02:34 ERROR (MainThread) [custom_components.hacs] <Integration AlexxIT/SonoffLAN> Cannot connect to host api.github.com:443 ssl:default [Try again]
2022-03-30 20:02:40 ERROR (MainThread) [custom_components.hacs] <Integration hacs/integration> Cannot connect to host api.github.com:443 ssl:default [Try again]
2022-03-30 20:03:47 ERROR (MainThread) [async_upnp_client.ssdp] Received error: [Errno 101] Network unreachable, transport: <_SelectorDatagramTransport fd=15 read=polling write=<idle, bufsize=0>>
2022-03-30 20:03:47 ERROR (MainThread) [async_upnp_client.ssdp] Received error: [Errno 101] Network unreachable, transport: <_SelectorDatagramTransport fd=15 read=polling write=<idle, bufsize=0>>
2022-03-30 20:05:47 ERROR (MainThread) [async_upnp_client.ssdp] Received error: [Errno 101] Network unreachable, transport: <_SelectorDatagramTransport fd=15 read=polling write=<idle, bufsize=0>>
2022-03-30 20:05:47 ERROR (MainThread) [async_upnp_client.ssdp] Received error: [Errno 101] Network unreachable, transport: <_SelectorDatagramTransport fd=15 read=polling write=<idle, bufsize=0>>
2022-03-30 20:07:47 ERROR (MainThread) [async_upnp_client.ssdp] Received error: [Errno 101] Network unreachable, transport: <_SelectorDatagramTransport fd=15 read=polling write=<idle, bufsize=0>>
2022-03-30 20:07:47 ERROR (MainThread) [async_upnp_client.ssdp] Received error: [Errno 101] Network unreachable, transport: <_SelectorDatagramTransport fd=15 read=polling write=<idle, bufsize=0>>
2022-03-30 20:09:47 ERROR (MainThread) [async_upnp_client.ssdp] Received error: [Errno 101] Network unreachable, transport: <_SelectorDatagramTransport fd=15 read=polling write=<idle, bufsize=0>>
2022-03-30 20:09:47 ERROR (MainThread) [async_upnp_client.ssdp] Received error: [Errno 101] Network unreachable, transport: <_SelectorDatagramTransport fd=15 read=polling write=<idle, bufsize=0>>
2022-03-30 20:10:41 ERROR (MainThread) [metno] Access to https://aa015h6buqvih86i1.api.met.no/weatherapi/locationforecast/2.0/complete returned error 'ClientConnectorError'
2022-03-30 20:11:47 ERROR (MainThread) [async_upnp_client.ssdp] Received error: [Errno 101] Network unreachable, transport: <_SelectorDatagramTransport fd=15 read=polling write=<idle, bufsize=0>>
2022-03-30 20:11:47 ERROR (MainThread) [async_upnp_client.ssdp] Received error: [Errno 101] Network unreachable, transport: <_SelectorDatagramTransport fd=15 read=polling write=<idle, bufsize=0>>
2022-03-30 20:12:08 ERROR (MainThread) [custom_components.hacs] Request exception for 'https://api.github.com/rate_limit' with - Cannot connect to host api.github.com:443 ssl:default [Try again]
Traceback (most recent call last):
  File "/config/custom_components/hacs/base.py", line 427, in async_can_update
    response = await self.async_github_api_method(self.githubapi.rate_limit)
  File "/config/custom_components/hacs/base.py", line 478, in async_github_api_method
    raise HacsException(_exception)
custom_components.hacs.exceptions.HacsException: Request exception for 'https://api.github.com/rate_limit' with - Cannot connect to host api.github.com:443 ssl:default [Try again]
2022-03-30 20:13:47 ERROR (MainThread) [async_upnp_client.ssdp] Received error: [Errno 101] Network unreachable, transport: <_SelectorDatagramTransport fd=15 read=polling write=<idle, bufsize=0>>
2022-03-30 20:13:47 ERROR (MainThread) [async_upnp_client.ssdp] Received error: [Errno 101] Network unreachable, transport: <_SelectorDatagramTransport fd=15 read=polling write=<idle, bufsize=0>>
2022-03-30 20:15:47 ERROR (MainThread) [async_upnp_client.ssdp] Received error: [Errno 101] Network unreachable, transport: <_SelectorDatagramTransport fd=15 read=polling write=<idle, bufsize=0>>
2022-03-30 20:15:47 ERROR (MainThread) [async_upnp_client.ssdp] Received error: [Errno 101] Network unreachable, transport: <_SelectorDatagramTransport fd=15 read=polling write=<idle, bufsize=0>>
2022-03-30 20:17:47 ERROR (MainThread) [async_upnp_client.ssdp] Received error: [Errno 101] Network unreachable, transport: <_SelectorDatagramTransport fd=15 read=polling write=<idle, bufsize=0>>
2022-03-30 20:17:47 ERROR (MainThread) [async_upnp_client.ssdp] Received error: [Errno 101] Network unreachable, transport: <_SelectorDatagramTransport fd=15 read=polling write=<idle, bufsize=0>>
2022-03-30 20:19:47 ERROR (MainThread) [async_upnp_client.ssdp] Received error: [Errno 101] Network unreachable, transport: <_SelectorDatagramTransport fd=15 read=polling write=<idle, bufsize=0>>
2022-03-30 20:19:47 ERROR (MainThread) [async_upnp_client.ssdp] Received error: [Errno 101] Network unreachable, transport: <_SelectorDatagramTransport fd=15 read=polling write=<idle, bufsize=0>>
2022-03-30 21:02:23 ERROR (MainThread) [homeassistant] Error doing job: Task exception was never retrieved
Traceback (most recent call last):
  File "/usr/src/homeassistant/homeassistant/components/dhcp/__init__.py", line 287, in async_discover
    for host in await self._discover_hosts.async_discover():
  File "/usr/local/lib/python3.9/site-packages/aiodiscover/discovery.py", line 143, in async_discover
    sys_network_data = await loop.run_in_executor(None, self._get_sys_network_data)
  File "/usr/local/lib/python3.9/concurrent/futures/thread.py", line 58, in run
    result = self.fn(*self.args, **self.kwargs)
  File "/usr/local/lib/python3.9/site-packages/aiodiscover/discovery.py", line 137, in _get_sys_network_data
    sys_network_data.setup()
  File "/usr/local/lib/python3.9/site-packages/aiodiscover/network.py", line 155, in setup
    self.network = get_network(self.local_ip, self.adapters)
  File "/usr/local/lib/python3.9/site-packages/aiodiscover/network.py", line 74, in get_network
    return ip_network(f"{local_ip}/{network_prefix}", False)
  File "/usr/local/lib/python3.9/ipaddress.py", line 83, in ip_network
    raise ValueError('%r does not appear to be an IPv4 or IPv6 network' %
ValueError: 'None/24' does not appear to be an IPv4 or IPv6 network
2022-03-30 22:24:07 ERROR (MainThread) [homeassistant.components.ipp.coordinator] Error fetching ipp data: Invalid response from API: Timeout occurred while connecting to IPP server.
2022-03-30 22:37:34 ERROR (MainThread) [homeassistant.components.ipp.coordinator] Error fetching ipp data: Invalid response from API: Timeout occurred while connecting to IPP server.
2022-03-31 04:35:04 ERROR (MainThread) [homeassistant.components.ipp.coordinator] Error fetching ipp data: Invalid response from API: Timeout occurred while connecting to IPP server.
2022-03-31 11:22:41 ERROR (MainThread) [homeassistant.components.apple_tv.config_flow] Unexpected exception
Traceback (most recent call last):
  File "/usr/src/homeassistant/homeassistant/components/apple_tv/config_flow.py", line 270, in async_find_device_wrapper
    await self.async_find_device(allow_exist)
  File "/usr/src/homeassistant/homeassistant/components/apple_tv/config_flow.py", line 283, in async_find_device
    self.atv, self.atv_identifiers = await device_scan(
  File "/usr/src/homeassistant/homeassistant/components/apple_tv/config_flow.py", line 57, in device_scan
    scan_result = await scan(loop, timeout=3, hosts=_host_filter(), aiozc=aiozc)
  File "/usr/local/lib/python3.9/site-packages/pyatv/__init__.py", line 58, in scan
    aiozc, hosts=[IPv4Address(host) for host in hosts]
  File "/usr/local/lib/python3.9/site-packages/pyatv/__init__.py", line 58, in <listcomp>
    aiozc, hosts=[IPv4Address(host) for host in hosts]
  File "/usr/local/lib/python3.9/ipaddress.py", line 1307, in __init__
    self._ip = self._ip_int_from_string(addr_str)
  File "/usr/local/lib/python3.9/ipaddress.py", line 1194, in _ip_int_from_string
    raise AddressValueError("Expected 4 octets in %r" % ip_str)
ipaddress.AddressValueError: Expected 4 octets in '2c0f:f4c0:118c:40e0:db:f108:bf16:6b22'
2022-04-01 00:03:08 ERROR (MainThread) [homeassistant.components.forecast_solar] Unexpected error fetching forecast_solar data: The Forecast.Solar API is unreachable, 
Traceback (most recent call last):
  File "/usr/src/homeassistant/homeassistant/helpers/update_coordinator.py", line 187, in _async_refresh
    self.data = await self._async_update_data()
  File "/usr/src/homeassistant/homeassistant/helpers/update_coordinator.py", line 147, in _async_update_data
    return await self.update_method()
  File "/usr/local/lib/python3.9/site-packages/forecast_solar/__init__.py", line 138, in estimate
    data = await self._request(
  File "/usr/local/lib/python3.9/site-packages/forecast_solar/__init__.py", line 105, in _request
    raise ForecastSolarConnectionError(
forecast_solar.exceptions.ForecastSolarConnectionError: The Forecast.Solar API is unreachable, 
2022-04-01 01:03:40 ERROR (MainThread) [homeassistant.components.forecast_solar] Unexpected error fetching forecast_solar data: The Forecast.Solar API is unreachable, 
Traceback (most recent call last):
  File "/usr/src/homeassistant/homeassistant/helpers/update_coordinator.py", line 187, in _async_refresh
    self.data = await self._async_update_data()
  File "/usr/src/homeassistant/homeassistant/helpers/update_coordinator.py", line 147, in _async_update_data
    return await self.update_method()
  File "/usr/local/lib/python3.9/site-packages/forecast_solar/__init__.py", line 138, in estimate
    data = await self._request(
  File "/usr/local/lib/python3.9/site-packages/forecast_solar/__init__.py", line 105, in _request
    raise ForecastSolarConnectionError(
forecast_solar.exceptions.ForecastSolarConnectionError: The Forecast.Solar API is unreachable, 
2022-04-01 02:04:12 ERROR (MainThread) [homeassistant.components.forecast_solar] Unexpected error fetching forecast_solar data: The Forecast.Solar API is unreachable, 
Traceback (most recent call last):
  File "/usr/src/homeassistant/homeassistant/helpers/update_coordinator.py", line 187, in _async_refresh
    self.data = await self._async_update_data()
  File "/usr/src/homeassistant/homeassistant/helpers/update_coordinator.py", line 147, in _async_update_data
    return await self.update_method()
  File "/usr/local/lib/python3.9/site-packages/forecast_solar/__init__.py", line 138, in estimate
    data = await self._request(
  File "/usr/local/lib/python3.9/site-packages/forecast_solar/__init__.py", line 105, in _request
    raise ForecastSolarConnectionError(
forecast_solar.exceptions.ForecastSolarConnectionError: The Forecast.Solar API is unreachable, 
2022-04-01 04:09:44 ERROR (MainThread) [homeassistant.components.forecast_solar] Unexpected error fetching forecast_solar data: The Forecast.Solar API is unreachable, 
Traceback (most recent call last):
  File "/usr/src/homeassistant/homeassistant/helpers/update_coordinator.py", line 187, in _async_refresh
    self.data = await self._async_update_data()
  File "/usr/src/homeassistant/homeassistant/helpers/update_coordinator.py", line 147, in _async_update_data
    return await self.update_method()
  File "/usr/local/lib/python3.9/site-packages/forecast_solar/__init__.py", line 138, in estimate
    data = await self._request(
  File "/usr/local/lib/python3.9/site-packages/forecast_solar/__init__.py", line 105, in _request
    raise ForecastSolarConnectionError(
forecast_solar.exceptions.ForecastSolarConnectionError: The Forecast.Solar API is unreachable, 
2022-04-01 05:10:16 ERROR (MainThread) [homeassistant.components.forecast_solar] Unexpected error fetching forecast_solar data: The Forecast.Solar API is unreachable, 
Traceback (most recent call last):
  File "/usr/src/homeassistant/homeassistant/helpers/update_coordinator.py", line 187, in _async_refresh
    self.data = await self._async_update_data()
  File "/usr/src/homeassistant/homeassistant/helpers/update_coordinator.py", line 147, in _async_update_data
    return await self.update_method()
  File "/usr/local/lib/python3.9/site-packages/forecast_solar/__init__.py", line 138, in estimate
    data = await self._request(
  File "/usr/local/lib/python3.9/site-packages/forecast_solar/__init__.py", line 105, in _request
    raise ForecastSolarConnectionError(
forecast_solar.exceptions.ForecastSolarConnectionError: The Forecast.Solar API is unreachable, 
2022-04-01 07:10:48 ERROR (MainThread) [homeassistant.components.forecast_solar] Unexpected error fetching forecast_solar data: The Forecast.Solar API is unreachable, 
Traceback (most recent call last):
  File "/usr/src/homeassistant/homeassistant/helpers/update_coordinator.py", line 187, in _async_refresh
    self.data = await self._async_update_data()
  File "/usr/src/homeassistant/homeassistant/helpers/update_coordinator.py", line 147, in _async_update_data
    return await self.update_method()
  File "/usr/local/lib/python3.9/site-packages/forecast_solar/__init__.py", line 138, in estimate
    data = await self._request(
  File "/usr/local/lib/python3.9/site-packages/forecast_solar/__init__.py", line 105, in _request
    raise ForecastSolarConnectionError(
forecast_solar.exceptions.ForecastSolarConnectionError: The Forecast.Solar API is unreachable, 
2022-04-01 08:11:20 ERROR (MainThread) [homeassistant.components.forecast_solar] Unexpected error fetching forecast_solar data: The Forecast.Solar API is unreachable, 
Traceback (most recent call last):
  File "/usr/src/homeassistant/homeassistant/helpers/update_coordinator.py", line 187, in _async_refresh
    self.data = await self._async_update_data()
  File "/usr/src/homeassistant/homeassistant/helpers/update_coordinator.py", line 147, in _async_update_data
    return await self.update_method()
  File "/usr/local/lib/python3.9/site-packages/forecast_solar/__init__.py", line 138, in estimate
    data = await self._request(
  File "/usr/local/lib/python3.9/site-packages/forecast_solar/__init__.py", line 105, in _request
    raise ForecastSolarConnectionError(
forecast_solar.exceptions.ForecastSolarConnectionError: The Forecast.Solar API is unreachable, 
2022-04-01 10:11:53 ERROR (MainThread) [homeassistant.components.forecast_solar] Unexpected error fetching forecast_solar data: The Forecast.Solar API is unreachable, 
Traceback (most recent call last):
  File "/usr/src/homeassistant/homeassistant/helpers/update_coordinator.py", line 187, in _async_refresh
    self.data = await self._async_update_data()
  File "/usr/src/homeassistant/homeassistant/helpers/update_coordinator.py", line 147, in _async_update_data
    return await self.update_method()
  File "/usr/local/lib/python3.9/site-packages/forecast_solar/__init__.py", line 138, in estimate
    data = await self._request(
  File "/usr/local/lib/python3.9/site-packages/forecast_solar/__init__.py", line 105, in _request
    raise ForecastSolarConnectionError(
forecast_solar.exceptions.ForecastSolarConnectionError: The Forecast.Solar API is unreachable, 
2022-04-01 11:12:25 ERROR (MainThread) [homeassistant.components.forecast_solar] Unexpected error fetching forecast_solar data: The Forecast.Solar API is unreachable, 
Traceback (most recent call last):
  File "/usr/src/homeassistant/homeassistant/helpers/update_coordinator.py", line 187, in _async_refresh
    self.data = await self._async_update_data()
  File "/usr/src/homeassistant/homeassistant/helpers/update_coordinator.py", line 147, in _async_update_data
    return await self.update_method()
  File "/usr/local/lib/python3.9/site-packages/forecast_solar/__init__.py", line 138, in estimate
    data = await self._request(
  File "/usr/local/lib/python3.9/site-packages/forecast_solar/__init__.py", line 105, in _request
    raise ForecastSolarConnectionError(
forecast_solar.exceptions.ForecastSolarConnectionError: The Forecast.Solar API is unreachable, 
2022-04-01 13:12:57 ERROR (MainThread) [homeassistant.components.forecast_solar] Unexpected error fetching forecast_solar data: The Forecast.Solar API is unreachable, 
Traceback (most recent call last):
  File "/usr/src/homeassistant/homeassistant/helpers/update_coordinator.py", line 187, in _async_refresh
    self.data = await self._async_update_data()
  File "/usr/src/homeassistant/homeassistant/helpers/update_coordinator.py", line 147, in _async_update_data
    return await self.update_method()
  File "/usr/local/lib/python3.9/site-packages/forecast_solar/__init__.py", line 138, in estimate
    data = await self._request(
  File "/usr/local/lib/python3.9/site-packages/forecast_solar/__init__.py", line 105, in _request
    raise ForecastSolarConnectionError(
forecast_solar.exceptions.ForecastSolarConnectionError: The Forecast.Solar API is unreachable, 
2022-04-01 17:13:29 ERROR (MainThread) [homeassistant.components.forecast_solar] Unexpected error fetching forecast_solar data: The Forecast.Solar API is unreachable, 
Traceback (most recent call last):
  File "/usr/src/homeassistant/homeassistant/helpers/update_coordinator.py", line 187, in _async_refresh
    self.data = await self._async_update_data()
  File "/usr/src/homeassistant/homeassistant/helpers/update_coordinator.py", line 147, in _async_update_data
    return await self.update_method()
  File "/usr/local/lib/python3.9/site-packages/forecast_solar/__init__.py", line 138, in estimate
    data = await self._request(
  File "/usr/local/lib/python3.9/site-packages/forecast_solar/__init__.py", line 105, in _request
    raise ForecastSolarConnectionError(
forecast_solar.exceptions.ForecastSolarConnectionError: The Forecast.Solar API is unreachable, 
2022-04-01 20:15:41 ERROR (MainThread) [homeassistant.components.forecast_solar] Unexpected error fetching forecast_solar data: The Forecast.Solar API is unreachable, 
Traceback (most recent call last):
  File "/usr/src/homeassistant/homeassistant/helpers/update_coordinator.py", line 187, in _async_refresh
    self.data = await self._async_update_data()
  File "/usr/src/homeassistant/homeassistant/helpers/update_coordinator.py", line 147, in _async_update_data
    return await self.update_method()
  File "/usr/local/lib/python3.9/site-packages/forecast_solar/__init__.py", line 138, in estimate
    data = await self._request(
  File "/usr/local/lib/python3.9/site-packages/forecast_solar/__init__.py", line 105, in _request
    raise ForecastSolarConnectionError(
forecast_solar.exceptions.ForecastSolarConnectionError: The Forecast.Solar API is unreachable, 
2022-04-01 20:43:22 ERROR (MainThread) [homeassistant.components.ipp.coordinator] Error fetching ipp data: Invalid response from API: Timeout occurred while connecting to IPP server.
2022-04-02 08:51:59 ERROR (MainThread) [metno] Access to https://aa015h6buqvih86i1.api.met.no/weatherapi/locationforecast/2.0/complete returned error 'ClientConnectorError'
2022-04-02 13:46:33 ERROR (MainThread) [homeassistant.components.apple_tv.config_flow] Unexpected exception
Traceback (most recent call last):
  File "/usr/src/homeassistant/homeassistant/components/apple_tv/config_flow.py", line 270, in async_find_device_wrapper
    await self.async_find_device(allow_exist)
  File "/usr/src/homeassistant/homeassistant/components/apple_tv/config_flow.py", line 283, in async_find_device
    self.atv, self.atv_identifiers = await device_scan(
  File "/usr/src/homeassistant/homeassistant/components/apple_tv/config_flow.py", line 57, in device_scan
    scan_result = await scan(loop, timeout=3, hosts=_host_filter(), aiozc=aiozc)
  File "/usr/local/lib/python3.9/site-packages/pyatv/__init__.py", line 58, in scan
    aiozc, hosts=[IPv4Address(host) for host in hosts]
  File "/usr/local/lib/python3.9/site-packages/pyatv/__init__.py", line 58, in <listcomp>
    aiozc, hosts=[IPv4Address(host) for host in hosts]
  File "/usr/local/lib/python3.9/ipaddress.py", line 1307, in __init__
    self._ip = self._ip_int_from_string(addr_str)
  File "/usr/local/lib/python3.9/ipaddress.py", line 1194, in _ip_int_from_string
    raise AddressValueError("Expected 4 octets in %r" % ip_str)
ipaddress.AddressValueError: Expected 4 octets in '2c0f:f4c0:118c:40e0:db:f108:bf16:6b22'
2022-04-02 19:40:50 ERROR (MainThread) [homeassistant.components.ipp.coordinator] Error fetching ipp data: Invalid response from API: Timeout occurred while connecting to IPP server.
2022-04-02 22:56:38 ERROR (MainThread) [homeassistant.components.ipp.coordinator] Error fetching ipp data: Invalid response from API: Timeout occurred while connecting to IPP server.
2022-04-02 23:26:38 ERROR (MainThread) [homeassistant.components.ipp.coordinator] Error fetching ipp data: Invalid response from API: Timeout occurred while connecting to IPP server.
2022-04-03 00:07:37 ERROR (MainThread) [homeassistant.components.ipp.coordinator] Error fetching ipp data: Invalid response from API: Timeout occurred while connecting to IPP server.
2022-04-03 03:37:18 ERROR (MainThread) [homeassistant.components.ipp.coordinator] Error fetching ipp data: Invalid response from API: Timeout occurred while connecting to IPP server.
2022-04-03 05:47:29 ERROR (MainThread) [homeassistant.components.ipp.coordinator] Error fetching ipp data: Invalid response from API: Timeout occurred while connecting to IPP server.
2022-04-03 08:22:45 ERROR (MainThread) [homeassistant.components.ipp.coordinator] Error fetching ipp data: Invalid response from API: Timeout occurred while connecting to IPP server.
2022-04-03 17:43:42 ERROR (MainThread) [homeassistant.components.ipp.coordinator] Error fetching ipp data: Invalid response from API: Timeout occurred while connecting to IPP server.
2022-04-04 08:55:56 ERROR (MainThread) [homeassistant.components.ipp.coordinator] Error fetching ipp data: Invalid response from API: Timeout occurred while connecting to IPP server.
2022-04-04 11:11:21 ERROR (MainThread) [homeassistant.components.ipp.coordinator] Error fetching ipp data: Invalid response from API: Timeout occurred while connecting to IPP server.
2022-04-04 12:48:43 ERROR (MainThread) [homeassistant.components.ipp.coordinator] Error fetching ipp data: Invalid response from API: Timeout occurred while connecting to IPP server.
2022-04-04 13:39:20 ERROR (MainThread) [homeassistant.components.apple_tv.config_flow] Unexpected exception
Traceback (most recent call last):
  File "/usr/src/homeassistant/homeassistant/components/apple_tv/config_flow.py", line 270, in async_find_device_wrapper
    await self.async_find_device(allow_exist)
  File "/usr/src/homeassistant/homeassistant/components/apple_tv/config_flow.py", line 283, in async_find_device
    self.atv, self.atv_identifiers = await device_scan(
  File "/usr/src/homeassistant/homeassistant/components/apple_tv/config_flow.py", line 57, in device_scan
    scan_result = await scan(loop, timeout=3, hosts=_host_filter(), aiozc=aiozc)
  File "/usr/local/lib/python3.9/site-packages/pyatv/__init__.py", line 58, in scan
    aiozc, hosts=[IPv4Address(host) for host in hosts]
  File "/usr/local/lib/python3.9/site-packages/pyatv/__init__.py", line 58, in <listcomp>
    aiozc, hosts=[IPv4Address(host) for host in hosts]
  File "/usr/local/lib/python3.9/ipaddress.py", line 1307, in __init__
    self._ip = self._ip_int_from_string(addr_str)
  File "/usr/local/lib/python3.9/ipaddress.py", line 1194, in _ip_int_from_string
    raise AddressValueError("Expected 4 octets in %r" % ip_str)
ipaddress.AddressValueError: Expected 4 octets in '2c0f:f4c0:118c:40e0:db:f108:bf16:6b22'
2022-04-04 14:11:42 ERROR (MainThread) [homeassistant.components.ipp.coordinator] Error fetching ipp data: Invalid response from API: Timeout occurred while connecting to IPP server.
2022-04-04 19:44:57 ERROR (MainThread) [homeassistant.components.apple_tv.config_flow] Unexpected exception
Traceback (most recent call last):
  File "/usr/src/homeassistant/homeassistant/components/apple_tv/config_flow.py", line 270, in async_find_device_wrapper
    await self.async_find_device(allow_exist)
  File "/usr/src/homeassistant/homeassistant/components/apple_tv/config_flow.py", line 283, in async_find_device
    self.atv, self.atv_identifiers = await device_scan(
  File "/usr/src/homeassistant/homeassistant/components/apple_tv/config_flow.py", line 57, in device_scan
    scan_result = await scan(loop, timeout=3, hosts=_host_filter(), aiozc=aiozc)
  File "/usr/local/lib/python3.9/site-packages/pyatv/__init__.py", line 58, in scan
    aiozc, hosts=[IPv4Address(host) for host in hosts]
  File "/usr/local/lib/python3.9/site-packages/pyatv/__init__.py", line 58, in <listcomp>
    aiozc, hosts=[IPv4Address(host) for host in hosts]
  File "/usr/local/lib/python3.9/ipaddress.py", line 1307, in __init__
    self._ip = self._ip_int_from_string(addr_str)
  File "/usr/local/lib/python3.9/ipaddress.py", line 1194, in _ip_int_from_string
    raise AddressValueError("Expected 4 octets in %r" % ip_str)
ipaddress.AddressValueError: Expected 4 octets in '2c0f:f4c0:118c:40e0:db:f108:bf16:6b22'
2022-04-04 21:52:42 ERROR (MainThread) [homeassistant.components.ipp.coordinator] Error fetching ipp data: Invalid response from API: Timeout occurred while connecting to IPP server.
2022-04-04 22:18:43 ERROR (MainThread) [homeassistant.components.ipp.coordinator] Error fetching ipp data: Invalid response from API: Timeout occurred while connecting to IPP server.
2022-04-04 23:02:03 ERROR (MainThread) [homeassistant.components.ipp.coordinator] Error fetching ipp data: Invalid response from API: Timeout occurred while connecting to IPP server.
2022-04-05 00:20:39 ERROR (MainThread) [homeassistant.components.ipp.coordinator] Error fetching ipp data: Invalid response from API: Timeout occurred while connecting to IPP server.
2022-04-05 04:41:04 ERROR (MainThread) [homeassistant.components.ipp.coordinator] Error fetching ipp data: Invalid response from API: Timeout occurred while connecting to IPP server.
2022-04-05 06:51:24 ERROR (MainThread) [homeassistant.components.ipp.coordinator] Error fetching ipp data: Invalid response from API: Timeout occurred while connecting to IPP server.
2022-04-05 07:21:22 ERROR (MainThread) [homeassistant.components.ipp.coordinator] Error fetching ipp data: Invalid response from API: Timeout occurred while connecting to IPP server.
2022-04-05 08:06:41 ERROR (MainThread) [homeassistant.components.ipp.coordinator] Error fetching ipp data: Invalid response from API: Timeout occurred while connecting to IPP server.
2022-04-05 08:31:28 ERROR (MainThread) [homeassistant.components.ipp.coordinator] Error fetching ipp data: Invalid response from API: Timeout occurred while connecting to IPP server.
2022-04-05 08:36:41 ERROR (MainThread) [homeassistant.components.ipp.coordinator] Error fetching ipp data: Invalid response from API: Timeout occurred while connecting to IPP server.
2022-04-05 09:51:40 ERROR (MainThread) [homeassistant.components.ipp.coordinator] Error fetching ipp data: Invalid response from API: Timeout occurred while connecting to IPP server.
2022-04-05 10:36:53 ERROR (MainThread) [homeassistant.components.ipp.coordinator] Error fetching ipp data: Invalid response from API: Timeout occurred while connecting to IPP server.
2022-04-05 11:12:02 ERROR (MainThread) [homeassistant.components.ipp.coordinator] Error fetching ipp data: Invalid response from API: Timeout occurred while connecting to IPP server.
2022-04-05 12:16:53 ERROR (MainThread) [homeassistant.components.ipp.coordinator] Error fetching ipp data: Invalid response from API: Timeout occurred while connecting to IPP server.
2022-04-05 16:27:49 ERROR (MainThread) [homeassistant.components.ipp.coordinator] Error fetching ipp data: Invalid response from API: Timeout occurred while connecting to IPP server.
2022-04-05 21:28:32 ERROR (MainThread) [homeassistant.components.ipp.coordinator] Error fetching ipp data: Invalid response from API: Timeout occurred while connecting to IPP server.
2022-04-06 01:59:10 ERROR (MainThread) [homeassistant.components.ipp.coordinator] Error fetching ipp data: Invalid response from API: Timeout occurred while connecting to IPP server.
2022-04-06 05:14:13 ERROR (MainThread) [homeassistant.components.ipp.coordinator] Error fetching ipp data: Invalid response from API: Timeout occurred while connecting to IPP server.
2022-04-06 06:34:38 ERROR (MainThread) [homeassistant.components.ipp.coordinator] Error fetching ipp data: Invalid response from API: Timeout occurred while connecting to IPP server.
2022-04-06 10:45:12 ERROR (MainThread) [homeassistant.components.ipp.coordinator] Error fetching ipp data: Invalid response from API: Timeout occurred while connecting to IPP server.
2022-04-06 14:40:48 ERROR (MainThread) [homeassistant.components.ipp.coordinator] Error fetching ipp data: Invalid response from API: Timeout occurred while connecting to IPP server.
2022-04-06 15:18:25 WARNING (MainThread) [homeassistant.components.http.ban] Login attempt or request with invalid authentication from 102-182-235-195.ip.afrihost.joburg (102.182.235.195). (Mozilla/5.0 (Windows NT 10.0; Win64; x64) AppleWebKit/537.36 (KHTML, like Gecko) Chrome/100.0.4896.60 Safari/537.36 Edg/100.0.1185.29)
2022-04-06 15:18:51 WARNING (MainThread) [homeassistant.components.http.ban] Login attempt or request with invalid authentication from 102-182-235-195.ip.afrihost.joburg (102.182.235.195). (Mozilla/5.0 (Windows NT 10.0; Win64; x64) AppleWebKit/537.36 (KHTML, like Gecko) Chrome/100.0.4896.60 Safari/537.36 Edg/100.0.1185.29)
2022-04-06 19:31:14 ERROR (MainThread) [homeassistant.components.ipp.coordinator] Error fetching ipp data: Invalid response from API: Timeout occurred while connecting to IPP server.
2022-04-06 23:22:05 ERROR (MainThread) [homeassistant.components.ipp.coordinator] Error fetching ipp data: Invalid response from API: Timeout occurred while connecting to IPP server.
2022-04-07 01:02:08 ERROR (MainThread) [homeassistant.components.ipp.coordinator] Error fetching ipp data: Invalid response from API: Timeout occurred while connecting to IPP server.
2022-04-07 02:12:08 ERROR (MainThread) [homeassistant.components.ipp.coordinator] Error fetching ipp data: Invalid response from API: Timeout occurred while connecting to IPP server.
2022-04-07 02:17:22 ERROR (MainThread) [homeassistant.components.ipp.coordinator] Error fetching ipp data: Invalid response from API: Timeout occurred while connecting to IPP server.
2022-04-07 04:22:38 ERROR (MainThread) [homeassistant.components.ipp.coordinator] Error fetching ipp data: Invalid response from API: Timeout occurred while connecting to IPP server.
2022-04-07 06:07:34 ERROR (MainThread) [homeassistant.components.ipp.coordinator] Error fetching ipp data: Invalid response from API: Timeout occurred while connecting to IPP server.
2022-04-07 08:47:59 ERROR (MainThread) [homeassistant.components.ipp.coordinator] Error fetching ipp data: Invalid response from API: Timeout occurred while connecting to IPP server.
2022-04-07 10:48:26 ERROR (MainThread) [homeassistant.components.ipp.coordinator] Error fetching ipp data: Invalid response from API: Timeout occurred while connecting to IPP server.
2022-04-07 13:48:43 ERROR (MainThread) [homeassistant.components.ipp.coordinator] Error fetching ipp data: Invalid response from API: Timeout occurred while connecting to IPP server.
2022-04-07 20:39:41 ERROR (MainThread) [homeassistant.components.ipp.coordinator] Error fetching ipp data: Invalid response from API: Timeout occurred while connecting to IPP server.
2022-04-07 22:24:43 ERROR (MainThread) [homeassistant.components.ipp.coordinator] Error fetching ipp data: Invalid response from API: Timeout occurred while connecting to IPP server.
2022-04-07 23:48:19 ERROR (MainThread) [homeassistant.components.ipp.coordinator] Error fetching ipp data: Invalid response from API: Timeout occurred while connecting to IPP server.
2022-04-08 01:05:11 ERROR (MainThread) [homeassistant.components.ipp.coordinator] Error fetching ipp data: Invalid response from API: Timeout occurred while connecting to IPP server.
2022-04-08 02:30:27 ERROR (MainThread) [homeassistant.components.ipp.coordinator] Error fetching ipp data: Invalid response from API: Timeout occurred while connecting to IPP server.
2022-04-08 03:55:41 ERROR (MainThread) [homeassistant.components.ipp.coordinator] Error fetching ipp data: Invalid response from API: Timeout occurred while connecting to IPP server.
2022-04-08 06:37:55 ERROR (MainThread) [homeassistant.components.ipp.coordinator] Error fetching ipp data: Invalid response from API: Timeout occurred while connecting to IPP server.
2022-04-08 14:07:10 ERROR (MainThread) [homeassistant.components.ipp.coordinator] Error fetching ipp data: Invalid response from API: Timeout occurred while connecting to IPP server.
2022-04-08 15:32:07 ERROR (MainThread) [homeassistant.components.ipp.coordinator] Error fetching ipp data: Invalid response from API: Timeout occurred while connecting to IPP server.
2022-04-08 15:57:26 ERROR (MainThread) [homeassistant.components.hassio] Failed to to call /available_updates - System is not ready with state: shutdown
